2016-02-19 14:04:19,517 INFO org.apache.hadoop.yarn.server.resourcemanager.ResourceManager: STARTUP_MSG: 
/************************************************************
STARTUP_MSG: Starting ResourceManager
STARTUP_MSG:   host = ubuntu/127.0.1.1
STARTUP_MSG:   args = []
STARTUP_MSG:   version = 2.6.4
STARTUP_MSG:   build = https://git-wip-us.apache.org/repos/asf/hadoop.git -r 5082c73637530b0b7e115f9625ed7fac69f937e6; compiled by 'jenkins' on 2016-02-12T09:45Z
STARTUP_MSG:   java = 1.7.0_79
************************************************************/
2016-02-19 14:04:19,529 INFO org.apache.hadoop.yarn.server.resourcemanager.ResourceManager: registered UNIX signal handlers for [TERM, HUP, INT]
2016-02-19 14:04:19,836 INFO org.apache.hadoop.conf.Configuration: found resource core-site.xml at file:/home/jon/.hadoop/core-site.xml
2016-02-19 14:04:20,007 INFO org.apache.hadoop.security.Groups: clearing userToGroupsMap cache
2016-02-19 14:04:20,124 INFO org.apache.hadoop.conf.Configuration: found resource yarn-site.xml at file:/home/jon/.hadoop/yarn-site.xml
2016-02-19 14:04:20,548 INFO org.apache.hadoop.yarn.event.AsyncDispatcher: Registering class org.apache.hadoop.yarn.server.resourcemanager.RMFatalEventType for class org.apache.hadoop.yarn.server.resourcemanager.ResourceManager$RMFatalEventDispatcher
2016-02-19 14:04:20,877 INFO org.apache.hadoop.yarn.server.resourcemanager.security.NMTokenSecretManagerInRM: NMTokenKeyRollingInterval: 86400000ms and NMTokenKeyActivationDelay: 900000ms
2016-02-19 14:04:20,906 INFO org.apache.hadoop.yarn.server.resourcemanager.security.RMContainerTokenSecretManager: ContainerTokenKeyRollingInterval: 86400000ms and ContainerTokenKeyActivationDelay: 900000ms
2016-02-19 14:04:20,911 INFO org.apache.hadoop.yarn.server.resourcemanager.security.AMRMTokenSecretManager: AMRMTokenKeyRollingInterval: 86400000ms and AMRMTokenKeyActivationDelay: 900000 ms
2016-02-19 14:04:20,947 INFO org.apache.hadoop.yarn.event.AsyncDispatcher: Registering class org.apache.hadoop.yarn.server.resourcemanager.recovery.RMStateStoreEventType for class org.apache.hadoop.yarn.server.resourcemanager.recovery.RMStateStore$ForwardingEventHandler
2016-02-19 14:04:20,948 INFO org.apache.hadoop.yarn.event.AsyncDispatcher: Registering class org.apache.hadoop.yarn.server.resourcemanager.NodesListManagerEventType for class org.apache.hadoop.yarn.server.resourcemanager.NodesListManager
2016-02-19 14:04:20,948 INFO org.apache.hadoop.yarn.server.resourcemanager.ResourceManager: Using Scheduler: org.apache.hadoop.yarn.server.resourcemanager.scheduler.capacity.CapacityScheduler
2016-02-19 14:04:20,972 INFO org.apache.hadoop.yarn.event.AsyncDispatcher: Registering class org.apache.hadoop.yarn.server.resourcemanager.scheduler.event.SchedulerEventType for class org.apache.hadoop.yarn.server.resourcemanager.ResourceManager$SchedulerEventDispatcher
2016-02-19 14:04:20,973 INFO org.apache.hadoop.yarn.event.AsyncDispatcher: Registering class org.apache.hadoop.yarn.server.resourcemanager.rmapp.RMAppEventType for class org.apache.hadoop.yarn.server.resourcemanager.ResourceManager$ApplicationEventDispatcher
2016-02-19 14:04:20,975 INFO org.apache.hadoop.yarn.event.AsyncDispatcher: Registering class org.apache.hadoop.yarn.server.resourcemanager.rmapp.attempt.RMAppAttemptEventType for class org.apache.hadoop.yarn.server.resourcemanager.ResourceManager$ApplicationAttemptEventDispatcher
2016-02-19 14:04:20,976 INFO org.apache.hadoop.yarn.event.AsyncDispatcher: Registering class org.apache.hadoop.yarn.server.resourcemanager.rmnode.RMNodeEventType for class org.apache.hadoop.yarn.server.resourcemanager.ResourceManager$NodeEventDispatcher
2016-02-19 14:04:21,072 INFO org.apache.hadoop.metrics2.impl.MetricsConfig: loaded properties from hadoop-metrics2.properties
2016-02-19 14:04:21,142 INFO org.apache.hadoop.metrics2.impl.MetricsSystemImpl: Scheduled snapshot period at 10 second(s).
2016-02-19 14:04:21,142 INFO org.apache.hadoop.metrics2.impl.MetricsSystemImpl: ResourceManager metrics system started
2016-02-19 14:04:21,192 INFO org.apache.hadoop.yarn.event.AsyncDispatcher: Registering class org.apache.hadoop.yarn.server.resourcemanager.RMAppManagerEventType for class org.apache.hadoop.yarn.server.resourcemanager.RMAppManager
2016-02-19 14:04:21,203 INFO org.apache.hadoop.yarn.event.AsyncDispatcher: Registering class org.apache.hadoop.yarn.server.resourcemanager.amlauncher.AMLauncherEventType for class org.apache.hadoop.yarn.server.resourcemanager.amlauncher.ApplicationMasterLauncher
2016-02-19 14:04:21,206 INFO org.apache.hadoop.yarn.server.resourcemanager.RMNMInfo: Registered RMNMInfo MBean
2016-02-19 14:04:21,208 INFO org.apache.hadoop.util.HostsFileReader: Refreshing hosts (include/exclude) list
2016-02-19 14:04:21,213 INFO org.apache.hadoop.conf.Configuration: found resource capacity-scheduler.xml at file:/home/jon/.hadoop/capacity-scheduler.xml
2016-02-19 14:04:21,336 INFO org.apache.hadoop.yarn.server.resourcemanager.scheduler.capacity.ParentQueue: root, capacity=1.0, asboluteCapacity=1.0, maxCapacity=1.0, asboluteMaxCapacity=1.0, state=RUNNING, acls=SUBMIT_APPLICATIONS:*ADMINISTER_QUEUE:*, labels=*,
, reservationsContinueLooking=true
2016-02-19 14:04:21,336 INFO org.apache.hadoop.yarn.server.resourcemanager.scheduler.capacity.ParentQueue: Initialized parent-queue root name=root, fullname=root
2016-02-19 14:04:21,361 INFO org.apache.hadoop.yarn.server.resourcemanager.scheduler.capacity.LeafQueue: Initializing default
capacity = 1.0 [= (float) configuredCapacity / 100 ]
asboluteCapacity = 1.0 [= parentAbsoluteCapacity * capacity ]
maxCapacity = 1.0 [= configuredMaxCapacity ]
absoluteMaxCapacity = 1.0 [= 1.0 maximumCapacity undefined, (parentAbsoluteMaxCapacity * maximumCapacity) / 100 otherwise ]
userLimit = 100 [= configuredUserLimit ]
userLimitFactor = 1.0 [= configuredUserLimitFactor ]
maxApplications = 10000 [= configuredMaximumSystemApplicationsPerQueue or (int)(configuredMaximumSystemApplications * absoluteCapacity)]
maxApplicationsPerUser = 10000 [= (int)(maxApplications * (userLimit / 100.0f) * userLimitFactor) ]
usedCapacity = 0.0 [= usedResourcesMemory / (clusterResourceMemory * absoluteCapacity)]
absoluteUsedCapacity = 0.0 [= usedResourcesMemory / clusterResourceMemory]
maxAMResourcePerQueuePercent = 0.1 [= configuredMaximumAMResourcePercent ]
minimumAllocationFactor = 0.875 [= (float)(maximumAllocationMemory - minimumAllocationMemory) / maximumAllocationMemory ]
numContainers = 0 [= currentNumContainers ]
state = RUNNING [= configuredState ]
acls = SUBMIT_APPLICATIONS:*ADMINISTER_QUEUE:* [= configuredAcls ]
nodeLocalityDelay = 40
labels=*,
nodeLocalityDelay = 40
reservationsContinueLooking = true

2016-02-19 14:04:21,362 INFO org.apache.hadoop.yarn.server.resourcemanager.scheduler.capacity.CapacityScheduler: Initialized queue: default: capacity=1.0, absoluteCapacity=1.0, usedResources=<memory:0, vCores:0>, usedCapacity=0.0, absoluteUsedCapacity=0.0, numApps=0, numContainers=0
2016-02-19 14:04:21,362 INFO org.apache.hadoop.yarn.server.resourcemanager.scheduler.capacity.CapacityScheduler: Initialized queue: root: numChildQueue= 1, capacity=1.0, absoluteCapacity=1.0, usedResources=<memory:0, vCores:0>usedCapacity=0.0, numApps=0, numContainers=0
2016-02-19 14:04:21,369 INFO org.apache.hadoop.yarn.server.resourcemanager.scheduler.capacity.CapacityScheduler: Initialized root queue root: numChildQueue= 1, capacity=1.0, absoluteCapacity=1.0, usedResources=<memory:0, vCores:0>usedCapacity=0.0, numApps=0, numContainers=0
2016-02-19 14:04:21,369 INFO org.apache.hadoop.yarn.server.resourcemanager.scheduler.capacity.CapacityScheduler: Initialized queue mappings, override: false
2016-02-19 14:04:21,369 INFO org.apache.hadoop.yarn.server.resourcemanager.scheduler.capacity.CapacityScheduler: Initialized CapacityScheduler with calculator=class org.apache.hadoop.yarn.util.resource.DefaultResourceCalculator, minimumAllocation=<<memory:1024, vCores:1>>, maximumAllocation=<<memory:8192, vCores:32>>, asynchronousScheduling=false, asyncScheduleInterval=5ms
2016-02-19 14:04:21,389 INFO org.apache.hadoop.yarn.server.resourcemanager.metrics.SystemMetricsPublisher: YARN system metrics publishing service is not enabled
2016-02-19 14:04:21,389 INFO org.apache.hadoop.yarn.server.resourcemanager.ResourceManager: Transitioning to active state
2016-02-19 14:04:21,420 INFO org.apache.hadoop.yarn.server.resourcemanager.security.RMContainerTokenSecretManager: Rolling master-key for container-tokens
2016-02-19 14:04:21,420 INFO org.apache.hadoop.yarn.server.resourcemanager.security.NMTokenSecretManagerInRM: Rolling master-key for nm-tokens
2016-02-19 14:04:21,420 INFO org.apache.hadoop.security.token.delegation.AbstractDelegationTokenSecretManager: Updating the current master key for generating delegation tokens
2016-02-19 14:04:21,421 INFO org.apache.hadoop.yarn.server.resourcemanager.security.RMDelegationTokenSecretManager: storing master key with keyID 1
2016-02-19 14:04:21,428 INFO org.apache.hadoop.security.token.delegation.AbstractDelegationTokenSecretManager: Starting expired delegation token remover thread, tokenRemoverScanInterval=60 min(s)
2016-02-19 14:04:21,429 INFO org.apache.hadoop.security.token.delegation.AbstractDelegationTokenSecretManager: Updating the current master key for generating delegation tokens
2016-02-19 14:04:21,429 INFO org.apache.hadoop.yarn.server.resourcemanager.security.RMDelegationTokenSecretManager: storing master key with keyID 2
2016-02-19 14:04:21,506 INFO org.apache.hadoop.ipc.CallQueueManager: Using callQueue class java.util.concurrent.LinkedBlockingQueue
2016-02-19 14:04:21,531 INFO org.apache.hadoop.ipc.Server: Starting Socket Reader #1 for port 8031
2016-02-19 14:04:21,574 INFO org.apache.hadoop.yarn.factories.impl.pb.RpcServerFactoryPBImpl: Adding protocol org.apache.hadoop.yarn.server.api.ResourceTrackerPB to the server
2016-02-19 14:04:21,575 INFO org.apache.hadoop.ipc.Server: IPC Server Responder: starting
2016-02-19 14:04:21,578 INFO org.apache.hadoop.ipc.Server: IPC Server listener on 8031: starting
2016-02-19 14:04:21,961 INFO org.apache.hadoop.ipc.CallQueueManager: Using callQueue class java.util.concurrent.LinkedBlockingQueue
2016-02-19 14:04:21,992 INFO org.apache.hadoop.ipc.Server: Starting Socket Reader #1 for port 8030
2016-02-19 14:04:22,020 INFO org.apache.hadoop.yarn.factories.impl.pb.RpcServerFactoryPBImpl: Adding protocol org.apache.hadoop.yarn.api.ApplicationMasterProtocolPB to the server
2016-02-19 14:04:22,030 INFO org.apache.hadoop.ipc.Server: IPC Server Responder: starting
2016-02-19 14:04:22,034 INFO org.apache.hadoop.ipc.Server: IPC Server listener on 8030: starting
2016-02-19 14:04:22,549 INFO org.apache.hadoop.ipc.CallQueueManager: Using callQueue class java.util.concurrent.LinkedBlockingQueue
2016-02-19 14:04:22,564 INFO org.apache.hadoop.ipc.Server: Starting Socket Reader #1 for port 8032
2016-02-19 14:04:22,571 INFO org.apache.hadoop.yarn.factories.impl.pb.RpcServerFactoryPBImpl: Adding protocol org.apache.hadoop.yarn.api.ApplicationClientProtocolPB to the server
2016-02-19 14:04:22,588 INFO org.apache.hadoop.ipc.Server: IPC Server Responder: starting
2016-02-19 14:04:22,593 INFO org.apache.hadoop.ipc.Server: IPC Server listener on 8032: starting
2016-02-19 14:04:22,871 INFO org.apache.hadoop.yarn.server.resourcemanager.ResourceManager: Transitioned to active state
2016-02-19 14:04:23,191 INFO org.mortbay.log: Logging to org.slf4j.impl.Log4jLoggerAdapter(org.mortbay.log) via org.mortbay.log.Slf4jLog
2016-02-19 14:04:23,199 INFO org.apache.hadoop.http.HttpRequestLog: Http request log for http.requests.resourcemanager is not defined
2016-02-19 14:04:23,288 INFO org.apache.hadoop.http.HttpServer2: Added global filter 'safety' (class=org.apache.hadoop.http.HttpServer2$QuotingInputFilter)
2016-02-19 14:04:23,477 INFO org.apache.hadoop.http.HttpServer2: Added filter RMAuthenticationFilter (class=org.apache.hadoop.yarn.server.security.http.RMAuthenticationFilter) to context cluster
2016-02-19 14:04:23,477 INFO org.apache.hadoop.http.HttpServer2: Added filter RMAuthenticationFilter (class=org.apache.hadoop.yarn.server.security.http.RMAuthenticationFilter) to context logs
2016-02-19 14:04:23,477 INFO org.apache.hadoop.http.HttpServer2: Added filter RMAuthenticationFilter (class=org.apache.hadoop.yarn.server.security.http.RMAuthenticationFilter) to context static
2016-02-19 14:04:23,478 INFO org.apache.hadoop.http.HttpServer2: Added filter static_user_filter (class=org.apache.hadoop.http.lib.StaticUserWebFilter$StaticUserFilter) to context cluster
2016-02-19 14:04:23,478 INFO org.apache.hadoop.http.HttpServer2: Added filter static_user_filter (class=org.apache.hadoop.http.lib.StaticUserWebFilter$StaticUserFilter) to context logs
2016-02-19 14:04:23,478 INFO org.apache.hadoop.http.HttpServer2: Added filter static_user_filter (class=org.apache.hadoop.http.lib.StaticUserWebFilter$StaticUserFilter) to context static
2016-02-19 14:04:23,504 INFO org.apache.hadoop.http.HttpServer2: adding path spec: /cluster/*
2016-02-19 14:04:23,504 INFO org.apache.hadoop.http.HttpServer2: adding path spec: /ws/*
2016-02-19 14:04:23,535 INFO org.apache.hadoop.http.HttpServer2: Jetty bound to port 8088
2016-02-19 14:04:23,535 INFO org.mortbay.log: jetty-6.1.26
2016-02-19 14:04:23,645 INFO org.mortbay.log: Extract jar:file:/usr/local/hadoop-2.6.4/share/hadoop/yarn/hadoop-yarn-common-2.6.4.jar!/webapps/cluster to /tmp/Jetty_localhost_8088_cluster____.3j26f5/webapp
2016-02-19 14:04:24,800 INFO org.apache.hadoop.security.token.delegation.AbstractDelegationTokenSecretManager: Updating the current master key for generating delegation tokens
2016-02-19 14:04:24,818 INFO org.apache.hadoop.security.token.delegation.AbstractDelegationTokenSecretManager: Starting expired delegation token remover thread, tokenRemoverScanInterval=60 min(s)
2016-02-19 14:04:24,867 INFO org.apache.hadoop.security.token.delegation.AbstractDelegationTokenSecretManager: Updating the current master key for generating delegation tokens
2016-02-19 14:04:25,028 INFO org.apache.hadoop.security.token.delegation.AbstractDelegationTokenSecretManager: Updating the current master key for generating delegation tokens
2016-02-19 14:04:25,052 INFO org.apache.hadoop.security.token.delegation.AbstractDelegationTokenSecretManager: Starting expired delegation token remover thread, tokenRemoverScanInterval=60 min(s)
2016-02-19 14:04:25,067 INFO org.apache.hadoop.security.token.delegation.AbstractDelegationTokenSecretManager: Updating the current master key for generating delegation tokens
2016-02-19 14:04:25,067 INFO org.apache.hadoop.security.token.delegation.AbstractDelegationTokenSecretManager: Updating the current master key for generating delegation tokens
2016-02-19 14:04:25,072 INFO org.apache.hadoop.security.token.delegation.AbstractDelegationTokenSecretManager: Starting expired delegation token remover thread, tokenRemoverScanInterval=60 min(s)
2016-02-19 14:04:25,094 INFO org.mortbay.log: Started HttpServer2$SelectChannelConnectorWithSafeStartup@localhost:8088
2016-02-19 14:04:25,094 INFO org.apache.hadoop.yarn.webapp.WebApps: Web app /cluster started at 8088
2016-02-19 14:04:25,100 INFO org.apache.hadoop.security.token.delegation.AbstractDelegationTokenSecretManager: Updating the current master key for generating delegation tokens
2016-02-19 14:04:26,730 INFO org.apache.hadoop.yarn.util.RackResolver: Resolved ubuntu to /default-rack
2016-02-19 14:04:26,733 INFO org.apache.hadoop.yarn.server.resourcemanager.ResourceTrackerService: NodeManager from node ubuntu(cmPort: 48650 httpPort: 8042) registered with capability: <memory:8192, vCores:8>, assigned nodeId ubuntu:48650
2016-02-19 14:04:27,158 INFO org.apache.hadoop.yarn.webapp.WebApps: Registered webapp guice modules
2016-02-19 14:04:27,185 INFO org.apache.hadoop.yarn.server.resourcemanager.rmnode.RMNodeImpl: ubuntu:48650 Node Transitioned from NEW to RUNNING
2016-02-19 14:04:27,187 INFO org.apache.hadoop.yarn.server.resourcemanager.scheduler.capacity.CapacityScheduler: Added node ubuntu:48650 clusterResource: <memory:8192, vCores:8>
2016-02-19 14:04:27,265 INFO org.apache.hadoop.ipc.CallQueueManager: Using callQueue class java.util.concurrent.LinkedBlockingQueue
2016-02-19 14:04:27,270 INFO org.apache.hadoop.ipc.Server: Starting Socket Reader #1 for port 8033
2016-02-19 14:04:27,278 INFO org.apache.hadoop.yarn.factories.impl.pb.RpcServerFactoryPBImpl: Adding protocol org.apache.hadoop.yarn.server.api.ResourceManagerAdministrationProtocolPB to the server
2016-02-19 14:04:27,284 INFO org.apache.hadoop.ipc.Server: IPC Server Responder: starting
2016-02-19 14:04:27,288 INFO org.apache.hadoop.ipc.Server: IPC Server listener on 8033: starting
2016-02-19 14:05:06,425 INFO org.apache.hadoop.yarn.server.resourcemanager.ClientRMService: Allocated new applicationId: 1
2016-02-19 14:05:08,541 INFO org.apache.hadoop.yarn.server.resourcemanager.rmapp.RMAppImpl: Storing application with id application_1455908661391_0001
2016-02-19 14:05:08,542 INFO org.apache.hadoop.yarn.server.resourcemanager.rmapp.RMAppImpl: application_1455908661391_0001 State change from NEW to NEW_SAVING
2016-02-19 14:05:08,543 INFO org.apache.hadoop.yarn.server.resourcemanager.ClientRMService: Application with id 1 submitted by user jon
2016-02-19 14:05:08,546 INFO org.apache.hadoop.yarn.server.resourcemanager.RMAuditLogger: USER=jon	IP=127.0.0.1	OPERATION=Submit Application Request	TARGET=ClientRMService	RESULT=SUCCESS	APPID=application_1455908661391_0001
2016-02-19 14:05:08,557 INFO org.apache.hadoop.yarn.server.resourcemanager.recovery.RMStateStore: Storing info for app: application_1455908661391_0001
2016-02-19 14:05:08,559 INFO org.apache.hadoop.yarn.server.resourcemanager.rmapp.RMAppImpl: application_1455908661391_0001 State change from NEW_SAVING to SUBMITTED
2016-02-19 14:05:08,563 INFO org.apache.hadoop.yarn.server.resourcemanager.scheduler.capacity.ParentQueue: Application added - appId: application_1455908661391_0001 user: jon leaf-queue of parent: root #applications: 1
2016-02-19 14:05:08,564 INFO org.apache.hadoop.yarn.server.resourcemanager.scheduler.capacity.CapacityScheduler: Accepted application application_1455908661391_0001 from user: jon, in queue: default
2016-02-19 14:05:08,585 INFO org.apache.hadoop.yarn.server.resourcemanager.rmapp.RMAppImpl: application_1455908661391_0001 State change from SUBMITTED to ACCEPTED
2016-02-19 14:05:08,610 INFO org.apache.hadoop.yarn.server.resourcemanager.ApplicationMasterService: Registering app attempt : appattempt_1455908661391_0001_000001
2016-02-19 14:05:08,613 INFO org.apache.hadoop.yarn.server.resourcemanager.rmapp.attempt.RMAppAttemptImpl: appattempt_1455908661391_0001_000001 State change from NEW to SUBMITTED
2016-02-19 14:05:08,644 WARN org.apache.hadoop.yarn.server.resourcemanager.scheduler.capacity.LeafQueue: maximum-am-resource-percent is insufficient to start a single application in queue, it is likely set too low. skipping enforcement to allow at least one application to start
2016-02-19 14:05:08,644 WARN org.apache.hadoop.yarn.server.resourcemanager.scheduler.capacity.LeafQueue: maximum-am-resource-percent is insufficient to start a single application in queue for user, it is likely set too low. skipping enforcement to allow at least one application to start
2016-02-19 14:05:08,646 INFO org.apache.hadoop.yarn.server.resourcemanager.scheduler.capacity.LeafQueue: Application application_1455908661391_0001 from user: jon activated in queue: default
2016-02-19 14:05:08,646 INFO org.apache.hadoop.yarn.server.resourcemanager.scheduler.capacity.LeafQueue: Application added - appId: application_1455908661391_0001 user: org.apache.hadoop.yarn.server.resourcemanager.scheduler.capacity.LeafQueue$User@63d8a9f3, leaf-queue: default #user-pending-applications: 0 #user-active-applications: 1 #queue-pending-applications: 0 #queue-active-applications: 1
2016-02-19 14:05:08,646 INFO org.apache.hadoop.yarn.server.resourcemanager.scheduler.capacity.CapacityScheduler: Added Application Attempt appattempt_1455908661391_0001_000001 to scheduler from user jon in queue default
2016-02-19 14:05:08,648 INFO org.apache.hadoop.yarn.server.resourcemanager.rmapp.attempt.RMAppAttemptImpl: appattempt_1455908661391_0001_000001 State change from SUBMITTED to SCHEDULED
2016-02-19 14:05:09,106 INFO org.apache.hadoop.yarn.server.resourcemanager.rmcontainer.RMContainerImpl: container_1455908661391_0001_01_000001 Container Transitioned from NEW to ALLOCATED
2016-02-19 14:05:09,106 INFO org.apache.hadoop.yarn.server.resourcemanager.RMAuditLogger: USER=jon	OPERATION=AM Allocated Container	TARGET=SchedulerApp	RESULT=SUCCESS	APPID=application_1455908661391_0001	CONTAINERID=container_1455908661391_0001_01_000001
2016-02-19 14:05:09,107 INFO org.apache.hadoop.yarn.server.resourcemanager.scheduler.SchedulerNode: Assigned container container_1455908661391_0001_01_000001 of capacity <memory:2048, vCores:1> on host ubuntu:48650, which has 1 containers, <memory:2048, vCores:1> used and <memory:6144, vCores:7> available after allocation
2016-02-19 14:05:09,107 INFO org.apache.hadoop.yarn.server.resourcemanager.scheduler.capacity.LeafQueue: assignedContainer application attempt=appattempt_1455908661391_0001_000001 container=Container: [ContainerId: container_1455908661391_0001_01_000001, NodeId: ubuntu:48650, NodeHttpAddress: ubuntu:8042, Resource: <memory:2048, vCores:1>, Priority: 0, Token: null, ] queue=default: capacity=1.0, absoluteCapacity=1.0, usedResources=<memory:0, vCores:0>, usedCapacity=0.0, absoluteUsedCapacity=0.0, numApps=1, numContainers=0 clusterResource=<memory:8192, vCores:8>
2016-02-19 14:05:09,108 INFO org.apache.hadoop.yarn.server.resourcemanager.scheduler.capacity.ParentQueue: Re-sorting assigned queue: root.default stats: default: capacity=1.0, absoluteCapacity=1.0, usedResources=<memory:2048, vCores:1>, usedCapacity=0.25, absoluteUsedCapacity=0.25, numApps=1, numContainers=1
2016-02-19 14:05:09,108 INFO org.apache.hadoop.yarn.server.resourcemanager.scheduler.capacity.ParentQueue: assignedContainer queue=root usedCapacity=0.25 absoluteUsedCapacity=0.25 used=<memory:2048, vCores:1> cluster=<memory:8192, vCores:8>
2016-02-19 14:05:09,131 INFO org.apache.hadoop.yarn.server.resourcemanager.security.NMTokenSecretManagerInRM: Sending NMToken for nodeId : ubuntu:48650 for container : container_1455908661391_0001_01_000001
2016-02-19 14:05:09,143 INFO org.apache.hadoop.yarn.server.resourcemanager.rmcontainer.RMContainerImpl: container_1455908661391_0001_01_000001 Container Transitioned from ALLOCATED to ACQUIRED
2016-02-19 14:05:09,144 INFO org.apache.hadoop.yarn.server.resourcemanager.security.NMTokenSecretManagerInRM: Clear node set for appattempt_1455908661391_0001_000001
2016-02-19 14:05:09,146 INFO org.apache.hadoop.yarn.server.resourcemanager.rmapp.attempt.RMAppAttemptImpl: Storing attempt: AppId: application_1455908661391_0001 AttemptId: appattempt_1455908661391_0001_000001 MasterContainer: Container: [ContainerId: container_1455908661391_0001_01_000001, NodeId: ubuntu:48650, NodeHttpAddress: ubuntu:8042, Resource: <memory:2048, vCores:1>, Priority: 0, Token: Token { kind: ContainerToken, service: 127.0.1.1:48650 }, ]
2016-02-19 14:05:09,150 INFO org.apache.hadoop.yarn.server.resourcemanager.rmapp.attempt.RMAppAttemptImpl: appattempt_1455908661391_0001_000001 State change from SCHEDULED to ALLOCATED_SAVING
2016-02-19 14:05:09,162 INFO org.apache.hadoop.yarn.server.resourcemanager.rmapp.attempt.RMAppAttemptImpl: appattempt_1455908661391_0001_000001 State change from ALLOCATED_SAVING to ALLOCATED
2016-02-19 14:05:09,165 INFO org.apache.hadoop.yarn.server.resourcemanager.amlauncher.AMLauncher: Launching masterappattempt_1455908661391_0001_000001
2016-02-19 14:05:09,204 INFO org.apache.hadoop.yarn.server.resourcemanager.amlauncher.AMLauncher: Setting up container Container: [ContainerId: container_1455908661391_0001_01_000001, NodeId: ubuntu:48650, NodeHttpAddress: ubuntu:8042, Resource: <memory:2048, vCores:1>, Priority: 0, Token: Token { kind: ContainerToken, service: 127.0.1.1:48650 }, ] for AM appattempt_1455908661391_0001_000001
2016-02-19 14:05:09,204 INFO org.apache.hadoop.yarn.server.resourcemanager.amlauncher.AMLauncher: Command to launch container container_1455908661391_0001_01_000001 : $JAVA_HOME/bin/java -Dlog4j.configuration=container-log4j.properties -Dyarn.app.container.log.dir=<LOG_DIR> -Dyarn.app.container.log.filesize=0 -Dhadoop.root.logger=INFO,CLA  -Xmx1024m org.apache.hadoop.mapreduce.v2.app.MRAppMaster 1><LOG_DIR>/stdout 2><LOG_DIR>/stderr 
2016-02-19 14:05:09,207 INFO org.apache.hadoop.yarn.server.resourcemanager.security.AMRMTokenSecretManager: Create AMRMToken for ApplicationAttempt: appattempt_1455908661391_0001_000001
2016-02-19 14:05:09,211 INFO org.apache.hadoop.yarn.server.resourcemanager.security.AMRMTokenSecretManager: Creating password for appattempt_1455908661391_0001_000001
2016-02-19 14:05:09,568 INFO org.apache.hadoop.yarn.server.resourcemanager.amlauncher.AMLauncher: Done launching container Container: [ContainerId: container_1455908661391_0001_01_000001, NodeId: ubuntu:48650, NodeHttpAddress: ubuntu:8042, Resource: <memory:2048, vCores:1>, Priority: 0, Token: Token { kind: ContainerToken, service: 127.0.1.1:48650 }, ] for AM appattempt_1455908661391_0001_000001
2016-02-19 14:05:09,568 INFO org.apache.hadoop.yarn.server.resourcemanager.rmapp.attempt.RMAppAttemptImpl: appattempt_1455908661391_0001_000001 State change from ALLOCATED to LAUNCHED
2016-02-19 14:05:10,104 INFO org.apache.hadoop.yarn.server.resourcemanager.rmcontainer.RMContainerImpl: container_1455908661391_0001_01_000001 Container Transitioned from ACQUIRED to RUNNING
2016-02-19 14:05:19,186 INFO SecurityLogger.org.apache.hadoop.ipc.Server: Auth successful for appattempt_1455908661391_0001_000001 (auth:SIMPLE)
2016-02-19 14:05:19,202 INFO org.apache.hadoop.yarn.server.resourcemanager.ApplicationMasterService: AM registration appattempt_1455908661391_0001_000001
2016-02-19 14:05:19,204 INFO org.apache.hadoop.yarn.server.resourcemanager.rmapp.attempt.RMAppAttemptImpl: appattempt_1455908661391_0001_000001 State change from LAUNCHED to RUNNING
2016-02-19 14:05:19,204 INFO org.apache.hadoop.yarn.server.resourcemanager.rmapp.RMAppImpl: application_1455908661391_0001 State change from ACCEPTED to RUNNING
2016-02-19 14:05:19,204 INFO org.apache.hadoop.yarn.server.resourcemanager.RMAuditLogger: USER=jon	IP=127.0.0.1	OPERATION=Register App Master	TARGET=ApplicationMasterService	RESULT=SUCCESS	APPID=application_1455908661391_0001	APPATTEMPTID=appattempt_1455908661391_0001_000001
2016-02-19 14:05:21,132 INFO org.apache.hadoop.yarn.server.resourcemanager.rmcontainer.RMContainerImpl: container_1455908661391_0001_01_000002 Container Transitioned from NEW to ALLOCATED
2016-02-19 14:05:21,132 INFO org.apache.hadoop.yarn.server.resourcemanager.RMAuditLogger: USER=jon	OPERATION=AM Allocated Container	TARGET=SchedulerApp	RESULT=SUCCESS	APPID=application_1455908661391_0001	CONTAINERID=container_1455908661391_0001_01_000002
2016-02-19 14:05:21,132 INFO org.apache.hadoop.yarn.server.resourcemanager.scheduler.SchedulerNode: Assigned container container_1455908661391_0001_01_000002 of capacity <memory:1024, vCores:1> on host ubuntu:48650, which has 2 containers, <memory:3072, vCores:2> used and <memory:5120, vCores:6> available after allocation
2016-02-19 14:05:21,132 INFO org.apache.hadoop.yarn.server.resourcemanager.scheduler.capacity.LeafQueue: assignedContainer application attempt=appattempt_1455908661391_0001_000001 container=Container: [ContainerId: container_1455908661391_0001_01_000002, NodeId: ubuntu:48650, NodeHttpAddress: ubuntu:8042, Resource: <memory:1024, vCores:1>, Priority: 20, Token: null, ] queue=default: capacity=1.0, absoluteCapacity=1.0, usedResources=<memory:2048, vCores:1>, usedCapacity=0.25, absoluteUsedCapacity=0.25, numApps=1, numContainers=1 clusterResource=<memory:8192, vCores:8>
2016-02-19 14:05:21,133 INFO org.apache.hadoop.yarn.server.resourcemanager.scheduler.capacity.ParentQueue: Re-sorting assigned queue: root.default stats: default: capacity=1.0, absoluteCapacity=1.0, usedResources=<memory:3072, vCores:2>, usedCapacity=0.375, absoluteUsedCapacity=0.375, numApps=1, numContainers=2
2016-02-19 14:05:21,133 INFO org.apache.hadoop.yarn.server.resourcemanager.scheduler.capacity.ParentQueue: assignedContainer queue=root usedCapacity=0.375 absoluteUsedCapacity=0.375 used=<memory:3072, vCores:2> cluster=<memory:8192, vCores:8>
2016-02-19 14:05:21,367 INFO org.apache.hadoop.yarn.server.resourcemanager.security.NMTokenSecretManagerInRM: Sending NMToken for nodeId : ubuntu:48650 for container : container_1455908661391_0001_01_000002
2016-02-19 14:05:21,369 INFO org.apache.hadoop.yarn.server.resourcemanager.rmcontainer.RMContainerImpl: container_1455908661391_0001_01_000002 Container Transitioned from ALLOCATED to ACQUIRED
2016-02-19 14:05:22,136 INFO org.apache.hadoop.yarn.server.resourcemanager.rmcontainer.RMContainerImpl: container_1455908661391_0001_01_000002 Container Transitioned from ACQUIRED to RUNNING
2016-02-19 14:05:22,389 INFO org.apache.hadoop.yarn.server.resourcemanager.scheduler.AppSchedulingInfo: checking for deactivate... 
2016-02-19 14:05:28,063 INFO org.apache.hadoop.yarn.server.resourcemanager.rmcontainer.RMContainerImpl: container_1455908661391_0001_01_000002 Container Transitioned from RUNNING to COMPLETED
2016-02-19 14:05:28,064 INFO org.apache.hadoop.yarn.server.resourcemanager.scheduler.common.fica.FiCaSchedulerApp: Completed container: container_1455908661391_0001_01_000002 in state: COMPLETED event:FINISHED
2016-02-19 14:05:28,064 INFO org.apache.hadoop.yarn.server.resourcemanager.RMAuditLogger: USER=jon	OPERATION=AM Released Container	TARGET=SchedulerApp	RESULT=SUCCESS	APPID=application_1455908661391_0001	CONTAINERID=container_1455908661391_0001_01_000002
2016-02-19 14:05:28,064 INFO org.apache.hadoop.yarn.server.resourcemanager.scheduler.SchedulerNode: Released container container_1455908661391_0001_01_000002 of capacity <memory:1024, vCores:1> on host ubuntu:48650, which currently has 1 containers, <memory:2048, vCores:1> used and <memory:6144, vCores:7> available, release resources=true
2016-02-19 14:05:28,065 INFO org.apache.hadoop.yarn.server.resourcemanager.scheduler.capacity.LeafQueue: default used=<memory:2048, vCores:1> numContainers=1 user=jon user-resources=<memory:2048, vCores:1>
2016-02-19 14:05:28,066 INFO org.apache.hadoop.yarn.server.resourcemanager.scheduler.capacity.LeafQueue: completedContainer container=Container: [ContainerId: container_1455908661391_0001_01_000002, NodeId: ubuntu:48650, NodeHttpAddress: ubuntu:8042, Resource: <memory:1024, vCores:1>, Priority: 20, Token: Token { kind: ContainerToken, service: 127.0.1.1:48650 }, ] queue=default: capacity=1.0, absoluteCapacity=1.0, usedResources=<memory:2048, vCores:1>, usedCapacity=0.25, absoluteUsedCapacity=0.25, numApps=1, numContainers=1 cluster=<memory:8192, vCores:8>
2016-02-19 14:05:28,067 INFO org.apache.hadoop.yarn.server.resourcemanager.scheduler.capacity.ParentQueue: completedContainer queue=root usedCapacity=0.25 absoluteUsedCapacity=0.25 used=<memory:2048, vCores:1> cluster=<memory:8192, vCores:8>
2016-02-19 14:05:28,067 INFO org.apache.hadoop.yarn.server.resourcemanager.scheduler.capacity.ParentQueue: Re-sorting completed queue: root.default stats: default: capacity=1.0, absoluteCapacity=1.0, usedResources=<memory:2048, vCores:1>, usedCapacity=0.25, absoluteUsedCapacity=0.25, numApps=1, numContainers=1
2016-02-19 14:05:28,067 INFO org.apache.hadoop.yarn.server.resourcemanager.scheduler.capacity.CapacityScheduler: Application attempt appattempt_1455908661391_0001_000001 released container container_1455908661391_0001_01_000002 on node: host: ubuntu:48650 #containers=1 available=6144 used=2048 with event: FINISHED
2016-02-19 14:05:29,064 INFO org.apache.hadoop.yarn.server.resourcemanager.rmcontainer.RMContainerImpl: container_1455908661391_0001_01_000003 Container Transitioned from NEW to ALLOCATED
2016-02-19 14:05:29,064 INFO org.apache.hadoop.yarn.server.resourcemanager.RMAuditLogger: USER=jon	OPERATION=AM Allocated Container	TARGET=SchedulerApp	RESULT=SUCCESS	APPID=application_1455908661391_0001	CONTAINERID=container_1455908661391_0001_01_000003
2016-02-19 14:05:29,065 INFO org.apache.hadoop.yarn.server.resourcemanager.scheduler.SchedulerNode: Assigned container container_1455908661391_0001_01_000003 of capacity <memory:1024, vCores:1> on host ubuntu:48650, which has 2 containers, <memory:3072, vCores:2> used and <memory:5120, vCores:6> available after allocation
2016-02-19 14:05:29,065 INFO org.apache.hadoop.yarn.server.resourcemanager.scheduler.capacity.LeafQueue: assignedContainer application attempt=appattempt_1455908661391_0001_000001 container=Container: [ContainerId: container_1455908661391_0001_01_000003, NodeId: ubuntu:48650, NodeHttpAddress: ubuntu:8042, Resource: <memory:1024, vCores:1>, Priority: 10, Token: null, ] queue=default: capacity=1.0, absoluteCapacity=1.0, usedResources=<memory:2048, vCores:1>, usedCapacity=0.25, absoluteUsedCapacity=0.25, numApps=1, numContainers=1 clusterResource=<memory:8192, vCores:8>
2016-02-19 14:05:29,065 INFO org.apache.hadoop.yarn.server.resourcemanager.scheduler.capacity.ParentQueue: Re-sorting assigned queue: root.default stats: default: capacity=1.0, absoluteCapacity=1.0, usedResources=<memory:3072, vCores:2>, usedCapacity=0.375, absoluteUsedCapacity=0.375, numApps=1, numContainers=2
2016-02-19 14:05:29,066 INFO org.apache.hadoop.yarn.server.resourcemanager.scheduler.capacity.ParentQueue: assignedContainer queue=root usedCapacity=0.375 absoluteUsedCapacity=0.375 used=<memory:3072, vCores:2> cluster=<memory:8192, vCores:8>
2016-02-19 14:05:29,429 INFO org.apache.hadoop.yarn.server.resourcemanager.rmcontainer.RMContainerImpl: container_1455908661391_0001_01_000003 Container Transitioned from ALLOCATED to ACQUIRED
2016-02-19 14:05:30,066 INFO org.apache.hadoop.yarn.server.resourcemanager.rmcontainer.RMContainerImpl: container_1455908661391_0001_01_000003 Container Transitioned from ACQUIRED to RUNNING
2016-02-19 14:05:30,441 INFO org.apache.hadoop.yarn.server.resourcemanager.scheduler.AppSchedulingInfo: checking for deactivate... 
2016-02-19 14:05:33,783 INFO org.apache.hadoop.yarn.server.resourcemanager.rmapp.attempt.RMAppAttemptImpl: Updating application attempt appattempt_1455908661391_0001_000001 with final state: FINISHING, and exit status: -1000
2016-02-19 14:05:33,784 INFO org.apache.hadoop.yarn.server.resourcemanager.rmapp.attempt.RMAppAttemptImpl: appattempt_1455908661391_0001_000001 State change from RUNNING to FINAL_SAVING
2016-02-19 14:05:33,784 INFO org.apache.hadoop.yarn.server.resourcemanager.rmapp.RMAppImpl: Updating application application_1455908661391_0001 with final state: FINISHING
2016-02-19 14:05:33,785 INFO org.apache.hadoop.yarn.server.resourcemanager.rmapp.RMAppImpl: application_1455908661391_0001 State change from RUNNING to FINAL_SAVING
2016-02-19 14:05:33,785 INFO org.apache.hadoop.yarn.server.resourcemanager.rmapp.attempt.RMAppAttemptImpl: appattempt_1455908661391_0001_000001 State change from FINAL_SAVING to FINISHING
2016-02-19 14:05:33,786 INFO org.apache.hadoop.yarn.server.resourcemanager.recovery.RMStateStore: Updating info for app: application_1455908661391_0001
2016-02-19 14:05:33,786 INFO org.apache.hadoop.yarn.server.resourcemanager.rmapp.RMAppImpl: application_1455908661391_0001 State change from FINAL_SAVING to FINISHING
2016-02-19 14:05:34,578 INFO org.apache.hadoop.yarn.server.resourcemanager.rmcontainer.RMContainerImpl: container_1455908661391_0001_01_000003 Container Transitioned from RUNNING to COMPLETED
2016-02-19 14:05:34,578 INFO org.apache.hadoop.yarn.server.resourcemanager.scheduler.common.fica.FiCaSchedulerApp: Completed container: container_1455908661391_0001_01_000003 in state: COMPLETED event:FINISHED
2016-02-19 14:05:34,606 INFO org.apache.hadoop.yarn.server.resourcemanager.RMAuditLogger: USER=jon	OPERATION=AM Released Container	TARGET=SchedulerApp	RESULT=SUCCESS	APPID=application_1455908661391_0001	CONTAINERID=container_1455908661391_0001_01_000003
2016-02-19 14:05:34,606 INFO org.apache.hadoop.yarn.server.resourcemanager.scheduler.SchedulerNode: Released container container_1455908661391_0001_01_000003 of capacity <memory:1024, vCores:1> on host ubuntu:48650, which currently has 1 containers, <memory:2048, vCores:1> used and <memory:6144, vCores:7> available, release resources=true
2016-02-19 14:05:34,606 INFO org.apache.hadoop.yarn.server.resourcemanager.scheduler.capacity.LeafQueue: default used=<memory:2048, vCores:1> numContainers=1 user=jon user-resources=<memory:2048, vCores:1>
2016-02-19 14:05:34,607 INFO org.apache.hadoop.yarn.server.resourcemanager.scheduler.capacity.LeafQueue: completedContainer container=Container: [ContainerId: container_1455908661391_0001_01_000003, NodeId: ubuntu:48650, NodeHttpAddress: ubuntu:8042, Resource: <memory:1024, vCores:1>, Priority: 10, Token: Token { kind: ContainerToken, service: 127.0.1.1:48650 }, ] queue=default: capacity=1.0, absoluteCapacity=1.0, usedResources=<memory:2048, vCores:1>, usedCapacity=0.25, absoluteUsedCapacity=0.25, numApps=1, numContainers=1 cluster=<memory:8192, vCores:8>
2016-02-19 14:05:34,607 INFO org.apache.hadoop.yarn.server.resourcemanager.scheduler.capacity.ParentQueue: completedContainer queue=root usedCapacity=0.25 absoluteUsedCapacity=0.25 used=<memory:2048, vCores:1> cluster=<memory:8192, vCores:8>
2016-02-19 14:05:34,607 INFO org.apache.hadoop.yarn.server.resourcemanager.scheduler.capacity.ParentQueue: Re-sorting completed queue: root.default stats: default: capacity=1.0, absoluteCapacity=1.0, usedResources=<memory:2048, vCores:1>, usedCapacity=0.25, absoluteUsedCapacity=0.25, numApps=1, numContainers=1
2016-02-19 14:05:34,607 INFO org.apache.hadoop.yarn.server.resourcemanager.scheduler.capacity.CapacityScheduler: Application attempt appattempt_1455908661391_0001_000001 released container container_1455908661391_0001_01_000003 on node: host: ubuntu:48650 #containers=1 available=6144 used=2048 with event: FINISHED
2016-02-19 14:05:34,793 INFO org.apache.hadoop.yarn.server.resourcemanager.ApplicationMasterService: application_1455908661391_0001 unregistered successfully. 
2016-02-19 14:05:40,598 INFO org.apache.hadoop.yarn.server.resourcemanager.rmcontainer.RMContainerImpl: container_1455908661391_0001_01_000001 Container Transitioned from RUNNING to COMPLETED
2016-02-19 14:05:40,598 INFO org.apache.hadoop.yarn.server.resourcemanager.scheduler.common.fica.FiCaSchedulerApp: Completed container: container_1455908661391_0001_01_000001 in state: COMPLETED event:FINISHED
2016-02-19 14:05:40,598 INFO org.apache.hadoop.yarn.server.resourcemanager.RMAuditLogger: USER=jon	OPERATION=AM Released Container	TARGET=SchedulerApp	RESULT=SUCCESS	APPID=application_1455908661391_0001	CONTAINERID=container_1455908661391_0001_01_000001
2016-02-19 14:05:40,599 INFO org.apache.hadoop.yarn.server.resourcemanager.scheduler.SchedulerNode: Released container container_1455908661391_0001_01_000001 of capacity <memory:2048, vCores:1> on host ubuntu:48650, which currently has 0 containers, <memory:0, vCores:0> used and <memory:8192, vCores:8> available, release resources=true
2016-02-19 14:05:40,599 INFO org.apache.hadoop.yarn.server.resourcemanager.scheduler.capacity.LeafQueue: default used=<memory:0, vCores:0> numContainers=0 user=jon user-resources=<memory:0, vCores:0>
2016-02-19 14:05:40,600 INFO org.apache.hadoop.yarn.server.resourcemanager.scheduler.capacity.LeafQueue: completedContainer container=Container: [ContainerId: container_1455908661391_0001_01_000001, NodeId: ubuntu:48650, NodeHttpAddress: ubuntu:8042, Resource: <memory:2048, vCores:1>, Priority: 0, Token: Token { kind: ContainerToken, service: 127.0.1.1:48650 }, ] queue=default: capacity=1.0, absoluteCapacity=1.0, usedResources=<memory:0, vCores:0>, usedCapacity=0.0, absoluteUsedCapacity=0.0, numApps=1, numContainers=0 cluster=<memory:8192, vCores:8>
2016-02-19 14:05:40,600 INFO org.apache.hadoop.yarn.server.resourcemanager.scheduler.capacity.ParentQueue: completedContainer queue=root usedCapacity=0.0 absoluteUsedCapacity=0.0 used=<memory:0, vCores:0> cluster=<memory:8192, vCores:8>
2016-02-19 14:05:40,600 INFO org.apache.hadoop.yarn.server.resourcemanager.scheduler.capacity.ParentQueue: Re-sorting completed queue: root.default stats: default: capacity=1.0, absoluteCapacity=1.0, usedResources=<memory:0, vCores:0>, usedCapacity=0.0, absoluteUsedCapacity=0.0, numApps=1, numContainers=0
2016-02-19 14:05:40,601 INFO org.apache.hadoop.yarn.server.resourcemanager.scheduler.capacity.CapacityScheduler: Application attempt appattempt_1455908661391_0001_000001 released container container_1455908661391_0001_01_000001 on node: host: ubuntu:48650 #containers=0 available=8192 used=0 with event: FINISHED
2016-02-19 14:05:40,601 INFO org.apache.hadoop.yarn.server.resourcemanager.ApplicationMasterService: Unregistering app attempt : appattempt_1455908661391_0001_000001
2016-02-19 14:05:40,625 INFO org.apache.hadoop.yarn.server.resourcemanager.security.AMRMTokenSecretManager: Application finished, removing password for appattempt_1455908661391_0001_000001
2016-02-19 14:05:40,625 INFO org.apache.hadoop.yarn.server.resourcemanager.rmapp.attempt.RMAppAttemptImpl: appattempt_1455908661391_0001_000001 State change from FINISHING to FINISHED
2016-02-19 14:05:40,629 INFO org.apache.hadoop.yarn.server.resourcemanager.rmapp.RMAppImpl: application_1455908661391_0001 State change from FINISHING to FINISHED
2016-02-19 14:05:40,629 INFO org.apache.hadoop.yarn.server.resourcemanager.scheduler.capacity.CapacityScheduler: Application Attempt appattempt_1455908661391_0001_000001 is done. finalState=FINISHED
2016-02-19 14:05:40,629 INFO org.apache.hadoop.yarn.server.resourcemanager.scheduler.AppSchedulingInfo: Application application_1455908661391_0001 requests cleared
2016-02-19 14:05:40,630 INFO org.apache.hadoop.yarn.server.resourcemanager.scheduler.capacity.LeafQueue: Application removed - appId: application_1455908661391_0001 user: jon queue: default #user-pending-applications: 0 #user-active-applications: 0 #queue-pending-applications: 0 #queue-active-applications: 0
2016-02-19 14:05:40,630 INFO org.apache.hadoop.yarn.server.resourcemanager.scheduler.capacity.ParentQueue: Application removed - appId: application_1455908661391_0001 user: jon leaf-queue of parent: root #applications: 0
2016-02-19 14:05:40,630 INFO org.apache.hadoop.yarn.server.resourcemanager.RMAuditLogger: USER=jon	OPERATION=Application Finished - Succeeded	TARGET=RMAppManager	RESULT=SUCCESS	APPID=application_1455908661391_0001
2016-02-19 14:05:40,631 INFO org.apache.hadoop.yarn.server.resourcemanager.amlauncher.AMLauncher: Cleaning master appattempt_1455908661391_0001_000001
2016-02-19 14:05:40,633 INFO org.apache.hadoop.yarn.server.resourcemanager.RMAppManager$ApplicationSummary: appId=application_1455908661391_0001,name=MissedConnectionAnalysis,user=jon,queue=default,state=FINISHED,trackingUrl=http://ubuntu:8088/proxy/application_1455908661391_0001/,appMasterHost=ubuntu,startTime=1455908708539,finishTime=1455908733784,finalStatus=SUCCEEDED
2016-02-19 14:05:41,655 INFO org.apache.hadoop.yarn.server.resourcemanager.scheduler.capacity.CapacityScheduler: Null container completed...
2016-02-19 14:05:49,825 INFO org.apache.hadoop.yarn.server.resourcemanager.ClientRMService: Allocated new applicationId: 2
2016-02-19 14:05:49,884 INFO org.apache.hadoop.yarn.server.resourcemanager.ClientRMService: Allocated new applicationId: 3
2016-02-19 14:05:57,941 INFO org.apache.hadoop.yarn.server.resourcemanager.ClientRMService: Application with id 2 submitted by user jon
2016-02-19 14:05:57,941 INFO org.apache.hadoop.yarn.server.resourcemanager.RMAuditLogger: USER=jon	IP=127.0.0.1	OPERATION=Submit Application Request	TARGET=ClientRMService	RESULT=SUCCESS	APPID=application_1455908661391_0002
2016-02-19 14:05:57,941 INFO org.apache.hadoop.yarn.server.resourcemanager.rmapp.RMAppImpl: Storing application with id application_1455908661391_0002
2016-02-19 14:05:57,942 INFO org.apache.hadoop.yarn.server.resourcemanager.rmapp.RMAppImpl: application_1455908661391_0002 State change from NEW to NEW_SAVING
2016-02-19 14:05:57,942 INFO org.apache.hadoop.yarn.server.resourcemanager.recovery.RMStateStore: Storing info for app: application_1455908661391_0002
2016-02-19 14:05:57,942 INFO org.apache.hadoop.yarn.server.resourcemanager.rmapp.RMAppImpl: application_1455908661391_0002 State change from NEW_SAVING to SUBMITTED
2016-02-19 14:05:57,942 INFO org.apache.hadoop.yarn.server.resourcemanager.scheduler.capacity.ParentQueue: Application added - appId: application_1455908661391_0002 user: jon leaf-queue of parent: root #applications: 1
2016-02-19 14:05:57,942 INFO org.apache.hadoop.yarn.server.resourcemanager.scheduler.capacity.CapacityScheduler: Accepted application application_1455908661391_0002 from user: jon, in queue: default
2016-02-19 14:05:57,946 INFO org.apache.hadoop.yarn.server.resourcemanager.rmapp.RMAppImpl: application_1455908661391_0002 State change from SUBMITTED to ACCEPTED
2016-02-19 14:05:57,947 INFO org.apache.hadoop.yarn.server.resourcemanager.ApplicationMasterService: Registering app attempt : appattempt_1455908661391_0002_000001
2016-02-19 14:05:57,947 INFO org.apache.hadoop.yarn.server.resourcemanager.rmapp.attempt.RMAppAttemptImpl: appattempt_1455908661391_0002_000001 State change from NEW to SUBMITTED
2016-02-19 14:05:57,958 WARN org.apache.hadoop.yarn.server.resourcemanager.scheduler.capacity.LeafQueue: maximum-am-resource-percent is insufficient to start a single application in queue, it is likely set too low. skipping enforcement to allow at least one application to start
2016-02-19 14:05:57,958 WARN org.apache.hadoop.yarn.server.resourcemanager.scheduler.capacity.LeafQueue: maximum-am-resource-percent is insufficient to start a single application in queue for user, it is likely set too low. skipping enforcement to allow at least one application to start
2016-02-19 14:05:57,958 INFO org.apache.hadoop.yarn.server.resourcemanager.scheduler.capacity.LeafQueue: Application application_1455908661391_0002 from user: jon activated in queue: default
2016-02-19 14:05:57,958 INFO org.apache.hadoop.yarn.server.resourcemanager.scheduler.capacity.LeafQueue: Application added - appId: application_1455908661391_0002 user: org.apache.hadoop.yarn.server.resourcemanager.scheduler.capacity.LeafQueue$User@5552749, leaf-queue: default #user-pending-applications: 0 #user-active-applications: 1 #queue-pending-applications: 0 #queue-active-applications: 1
2016-02-19 14:05:57,958 INFO org.apache.hadoop.yarn.server.resourcemanager.scheduler.capacity.CapacityScheduler: Added Application Attempt appattempt_1455908661391_0002_000001 to scheduler from user jon in queue default
2016-02-19 14:05:57,963 INFO org.apache.hadoop.yarn.server.resourcemanager.rmapp.attempt.RMAppAttemptImpl: appattempt_1455908661391_0002_000001 State change from SUBMITTED to SCHEDULED
2016-02-19 14:05:58,293 INFO org.apache.hadoop.yarn.server.resourcemanager.ClientRMService: Application with id 3 submitted by user jon
2016-02-19 14:05:58,294 INFO org.apache.hadoop.yarn.server.resourcemanager.RMAuditLogger: USER=jon	IP=127.0.0.1	OPERATION=Submit Application Request	TARGET=ClientRMService	RESULT=SUCCESS	APPID=application_1455908661391_0003
2016-02-19 14:05:58,294 INFO org.apache.hadoop.yarn.server.resourcemanager.rmapp.RMAppImpl: Storing application with id application_1455908661391_0003
2016-02-19 14:05:58,294 INFO org.apache.hadoop.yarn.server.resourcemanager.rmapp.RMAppImpl: application_1455908661391_0003 State change from NEW to NEW_SAVING
2016-02-19 14:05:58,294 INFO org.apache.hadoop.yarn.server.resourcemanager.recovery.RMStateStore: Storing info for app: application_1455908661391_0003
2016-02-19 14:05:58,294 INFO org.apache.hadoop.yarn.server.resourcemanager.rmapp.RMAppImpl: application_1455908661391_0003 State change from NEW_SAVING to SUBMITTED
2016-02-19 14:05:58,295 INFO org.apache.hadoop.yarn.server.resourcemanager.scheduler.capacity.ParentQueue: Application added - appId: application_1455908661391_0003 user: jon leaf-queue of parent: root #applications: 2
2016-02-19 14:05:58,295 INFO org.apache.hadoop.yarn.server.resourcemanager.scheduler.capacity.CapacityScheduler: Accepted application application_1455908661391_0003 from user: jon, in queue: default
2016-02-19 14:05:58,295 INFO org.apache.hadoop.yarn.server.resourcemanager.rmapp.RMAppImpl: application_1455908661391_0003 State change from SUBMITTED to ACCEPTED
2016-02-19 14:05:58,295 INFO org.apache.hadoop.yarn.server.resourcemanager.ApplicationMasterService: Registering app attempt : appattempt_1455908661391_0003_000001
2016-02-19 14:05:58,295 INFO org.apache.hadoop.yarn.server.resourcemanager.rmapp.attempt.RMAppAttemptImpl: appattempt_1455908661391_0003_000001 State change from NEW to SUBMITTED
2016-02-19 14:05:58,296 INFO org.apache.hadoop.yarn.server.resourcemanager.scheduler.capacity.LeafQueue: not starting application as amIfStarted exceeds amLimit
2016-02-19 14:05:58,296 INFO org.apache.hadoop.yarn.server.resourcemanager.scheduler.capacity.LeafQueue: Application added - appId: application_1455908661391_0003 user: org.apache.hadoop.yarn.server.resourcemanager.scheduler.capacity.LeafQueue$User@5552749, leaf-queue: default #user-pending-applications: 1 #user-active-applications: 1 #queue-pending-applications: 1 #queue-active-applications: 1
2016-02-19 14:05:58,296 INFO org.apache.hadoop.yarn.server.resourcemanager.scheduler.capacity.CapacityScheduler: Added Application Attempt appattempt_1455908661391_0003_000001 to scheduler from user jon in queue default
2016-02-19 14:05:58,297 INFO org.apache.hadoop.yarn.server.resourcemanager.rmapp.attempt.RMAppAttemptImpl: appattempt_1455908661391_0003_000001 State change from SUBMITTED to SCHEDULED
2016-02-19 14:05:58,746 INFO org.apache.hadoop.yarn.server.resourcemanager.rmcontainer.RMContainerImpl: container_1455908661391_0002_01_000001 Container Transitioned from NEW to ALLOCATED
2016-02-19 14:05:58,746 INFO org.apache.hadoop.yarn.server.resourcemanager.RMAuditLogger: USER=jon	OPERATION=AM Allocated Container	TARGET=SchedulerApp	RESULT=SUCCESS	APPID=application_1455908661391_0002	CONTAINERID=container_1455908661391_0002_01_000001
2016-02-19 14:05:58,746 INFO org.apache.hadoop.yarn.server.resourcemanager.scheduler.SchedulerNode: Assigned container container_1455908661391_0002_01_000001 of capacity <memory:2048, vCores:1> on host ubuntu:48650, which has 1 containers, <memory:2048, vCores:1> used and <memory:6144, vCores:7> available after allocation
2016-02-19 14:05:58,746 INFO org.apache.hadoop.yarn.server.resourcemanager.scheduler.capacity.LeafQueue: assignedContainer application attempt=appattempt_1455908661391_0002_000001 container=Container: [ContainerId: container_1455908661391_0002_01_000001, NodeId: ubuntu:48650, NodeHttpAddress: ubuntu:8042, Resource: <memory:2048, vCores:1>, Priority: 0, Token: null, ] queue=default: capacity=1.0, absoluteCapacity=1.0, usedResources=<memory:0, vCores:0>, usedCapacity=0.0, absoluteUsedCapacity=0.0, numApps=2, numContainers=0 clusterResource=<memory:8192, vCores:8>
2016-02-19 14:05:58,747 INFO org.apache.hadoop.yarn.server.resourcemanager.scheduler.capacity.ParentQueue: Re-sorting assigned queue: root.default stats: default: capacity=1.0, absoluteCapacity=1.0, usedResources=<memory:2048, vCores:1>, usedCapacity=0.25, absoluteUsedCapacity=0.25, numApps=2, numContainers=1
2016-02-19 14:05:58,747 INFO org.apache.hadoop.yarn.server.resourcemanager.scheduler.capacity.ParentQueue: assignedContainer queue=root usedCapacity=0.25 absoluteUsedCapacity=0.25 used=<memory:2048, vCores:1> cluster=<memory:8192, vCores:8>
2016-02-19 14:05:58,749 INFO org.apache.hadoop.yarn.server.resourcemanager.security.NMTokenSecretManagerInRM: Sending NMToken for nodeId : ubuntu:48650 for container : container_1455908661391_0002_01_000001
2016-02-19 14:05:58,751 INFO org.apache.hadoop.yarn.server.resourcemanager.rmcontainer.RMContainerImpl: container_1455908661391_0002_01_000001 Container Transitioned from ALLOCATED to ACQUIRED
2016-02-19 14:05:58,751 INFO org.apache.hadoop.yarn.server.resourcemanager.security.NMTokenSecretManagerInRM: Clear node set for appattempt_1455908661391_0002_000001
2016-02-19 14:05:58,751 INFO org.apache.hadoop.yarn.server.resourcemanager.rmapp.attempt.RMAppAttemptImpl: Storing attempt: AppId: application_1455908661391_0002 AttemptId: appattempt_1455908661391_0002_000001 MasterContainer: Container: [ContainerId: container_1455908661391_0002_01_000001, NodeId: ubuntu:48650, NodeHttpAddress: ubuntu:8042, Resource: <memory:2048, vCores:1>, Priority: 0, Token: Token { kind: ContainerToken, service: 127.0.1.1:48650 }, ]
2016-02-19 14:05:58,751 INFO org.apache.hadoop.yarn.server.resourcemanager.rmapp.attempt.RMAppAttemptImpl: appattempt_1455908661391_0002_000001 State change from SCHEDULED to ALLOCATED_SAVING
2016-02-19 14:05:58,751 INFO org.apache.hadoop.yarn.server.resourcemanager.rmapp.attempt.RMAppAttemptImpl: appattempt_1455908661391_0002_000001 State change from ALLOCATED_SAVING to ALLOCATED
2016-02-19 14:05:58,752 INFO org.apache.hadoop.yarn.server.resourcemanager.amlauncher.AMLauncher: Launching masterappattempt_1455908661391_0002_000001
2016-02-19 14:05:58,754 INFO org.apache.hadoop.yarn.server.resourcemanager.amlauncher.AMLauncher: Setting up container Container: [ContainerId: container_1455908661391_0002_01_000001, NodeId: ubuntu:48650, NodeHttpAddress: ubuntu:8042, Resource: <memory:2048, vCores:1>, Priority: 0, Token: Token { kind: ContainerToken, service: 127.0.1.1:48650 }, ] for AM appattempt_1455908661391_0002_000001
2016-02-19 14:05:58,754 INFO org.apache.hadoop.yarn.server.resourcemanager.amlauncher.AMLauncher: Command to launch container container_1455908661391_0002_01_000001 : $JAVA_HOME/bin/java -Dlog4j.configuration=container-log4j.properties -Dyarn.app.container.log.dir=<LOG_DIR> -Dyarn.app.container.log.filesize=0 -Dhadoop.root.logger=INFO,CLA  -Xmx1024m org.apache.hadoop.mapreduce.v2.app.MRAppMaster 1><LOG_DIR>/stdout 2><LOG_DIR>/stderr 
2016-02-19 14:05:58,754 INFO org.apache.hadoop.yarn.server.resourcemanager.security.AMRMTokenSecretManager: Create AMRMToken for ApplicationAttempt: appattempt_1455908661391_0002_000001
2016-02-19 14:05:58,754 INFO org.apache.hadoop.yarn.server.resourcemanager.security.AMRMTokenSecretManager: Creating password for appattempt_1455908661391_0002_000001
2016-02-19 14:05:58,774 INFO org.apache.hadoop.yarn.server.resourcemanager.amlauncher.AMLauncher: Done launching container Container: [ContainerId: container_1455908661391_0002_01_000001, NodeId: ubuntu:48650, NodeHttpAddress: ubuntu:8042, Resource: <memory:2048, vCores:1>, Priority: 0, Token: Token { kind: ContainerToken, service: 127.0.1.1:48650 }, ] for AM appattempt_1455908661391_0002_000001
2016-02-19 14:05:58,774 INFO org.apache.hadoop.yarn.server.resourcemanager.rmapp.attempt.RMAppAttemptImpl: appattempt_1455908661391_0002_000001 State change from ALLOCATED to LAUNCHED
2016-02-19 14:05:59,753 INFO org.apache.hadoop.yarn.server.resourcemanager.rmcontainer.RMContainerImpl: container_1455908661391_0002_01_000001 Container Transitioned from ACQUIRED to RUNNING
2016-02-19 14:14:21,411 INFO org.apache.hadoop.yarn.server.resourcemanager.scheduler.AbstractYarnScheduler: Release request cache is cleaned up
2016-02-19 14:17:41,468 INFO org.apache.hadoop.yarn.util.AbstractLivelinessMonitor: Expired:appattempt_1455908661391_0002_000001 Timed out after 600 secs
2016-02-19 14:17:41,472 INFO org.apache.hadoop.yarn.server.resourcemanager.rmapp.attempt.RMAppAttemptImpl: Updating application attempt appattempt_1455908661391_0002_000001 with final state: FAILED, and exit status: -1000
2016-02-19 14:17:41,472 INFO org.apache.hadoop.yarn.server.resourcemanager.rmapp.attempt.RMAppAttemptImpl: appattempt_1455908661391_0002_000001 State change from LAUNCHED to FINAL_SAVING
2016-02-19 14:17:41,476 INFO org.apache.hadoop.yarn.server.resourcemanager.ApplicationMasterService: Unregistering app attempt : appattempt_1455908661391_0002_000001
2016-02-19 14:17:41,480 INFO org.apache.hadoop.yarn.server.resourcemanager.security.AMRMTokenSecretManager: Application finished, removing password for appattempt_1455908661391_0002_000001
2016-02-19 14:17:41,481 INFO org.apache.hadoop.yarn.server.resourcemanager.rmapp.attempt.RMAppAttemptImpl: appattempt_1455908661391_0002_000001 State change from FINAL_SAVING to FAILED
2016-02-19 14:17:41,482 INFO org.apache.hadoop.yarn.server.resourcemanager.rmapp.RMAppImpl: The number of failed attempts is 1. The max attempts is 2
2016-02-19 14:17:41,484 INFO org.apache.hadoop.yarn.server.resourcemanager.scheduler.capacity.CapacityScheduler: Application Attempt appattempt_1455908661391_0002_000001 is done. finalState=FAILED
2016-02-19 14:17:41,490 INFO org.apache.hadoop.yarn.server.resourcemanager.ApplicationMasterService: Registering app attempt : appattempt_1455908661391_0002_000002
2016-02-19 14:17:41,490 INFO org.apache.hadoop.yarn.server.resourcemanager.amlauncher.AMLauncher: Cleaning master appattempt_1455908661391_0002_000001
2016-02-19 14:17:41,491 INFO org.apache.hadoop.yarn.server.resourcemanager.rmapp.attempt.RMAppAttemptImpl: appattempt_1455908661391_0002_000002 State change from NEW to SUBMITTED
2016-02-19 14:17:41,497 INFO org.apache.hadoop.yarn.server.resourcemanager.rmcontainer.RMContainerImpl: container_1455908661391_0002_01_000001 Container Transitioned from RUNNING to KILLED
2016-02-19 14:17:41,497 INFO org.apache.hadoop.yarn.server.resourcemanager.scheduler.common.fica.FiCaSchedulerApp: Completed container: container_1455908661391_0002_01_000001 in state: KILLED event:KILL
2016-02-19 14:17:41,497 INFO org.apache.hadoop.yarn.server.resourcemanager.RMAuditLogger: USER=jon	OPERATION=AM Released Container	TARGET=SchedulerApp	RESULT=SUCCESS	APPID=application_1455908661391_0002	CONTAINERID=container_1455908661391_0002_01_000001
2016-02-19 14:17:41,497 INFO org.apache.hadoop.yarn.server.resourcemanager.scheduler.SchedulerNode: Released container container_1455908661391_0002_01_000001 of capacity <memory:2048, vCores:1> on host ubuntu:48650, which currently has 0 containers, <memory:0, vCores:0> used and <memory:8192, vCores:8> available, release resources=true
2016-02-19 14:17:41,499 INFO org.apache.hadoop.yarn.server.resourcemanager.scheduler.capacity.LeafQueue: default used=<memory:0, vCores:0> numContainers=0 user=jon user-resources=<memory:0, vCores:0>
2016-02-19 14:17:41,499 INFO org.apache.hadoop.yarn.server.resourcemanager.scheduler.capacity.LeafQueue: completedContainer container=Container: [ContainerId: container_1455908661391_0002_01_000001, NodeId: ubuntu:48650, NodeHttpAddress: ubuntu:8042, Resource: <memory:2048, vCores:1>, Priority: 0, Token: Token { kind: ContainerToken, service: 127.0.1.1:48650 }, ] queue=default: capacity=1.0, absoluteCapacity=1.0, usedResources=<memory:0, vCores:0>, usedCapacity=0.0, absoluteUsedCapacity=0.0, numApps=2, numContainers=0 cluster=<memory:8192, vCores:8>
2016-02-19 14:17:41,499 INFO org.apache.hadoop.yarn.server.resourcemanager.scheduler.capacity.ParentQueue: completedContainer queue=root usedCapacity=0.0 absoluteUsedCapacity=0.0 used=<memory:0, vCores:0> cluster=<memory:8192, vCores:8>
2016-02-19 14:17:41,500 INFO org.apache.hadoop.yarn.server.resourcemanager.scheduler.capacity.ParentQueue: Re-sorting completed queue: root.default stats: default: capacity=1.0, absoluteCapacity=1.0, usedResources=<memory:0, vCores:0>, usedCapacity=0.0, absoluteUsedCapacity=0.0, numApps=2, numContainers=0
2016-02-19 14:17:41,500 INFO org.apache.hadoop.yarn.server.resourcemanager.scheduler.capacity.CapacityScheduler: Application attempt appattempt_1455908661391_0002_000001 released container container_1455908661391_0002_01_000001 on node: host: ubuntu:48650 #containers=0 available=8192 used=0 with event: KILL
2016-02-19 14:17:41,500 INFO org.apache.hadoop.yarn.server.resourcemanager.scheduler.AppSchedulingInfo: Application application_1455908661391_0002 requests cleared
2016-02-19 14:17:41,500 WARN org.apache.hadoop.yarn.server.resourcemanager.scheduler.capacity.LeafQueue: maximum-am-resource-percent is insufficient to start a single application in queue, it is likely set too low. skipping enforcement to allow at least one application to start
2016-02-19 14:17:41,500 WARN org.apache.hadoop.yarn.server.resourcemanager.scheduler.capacity.LeafQueue: maximum-am-resource-percent is insufficient to start a single application in queue for user, it is likely set too low. skipping enforcement to allow at least one application to start
2016-02-19 14:17:41,500 INFO org.apache.hadoop.yarn.server.resourcemanager.scheduler.capacity.LeafQueue: Application application_1455908661391_0003 from user: jon activated in queue: default
2016-02-19 14:17:41,500 INFO org.apache.hadoop.yarn.server.resourcemanager.scheduler.capacity.LeafQueue: Application removed - appId: application_1455908661391_0002 user: jon queue: default #user-pending-applications: 0 #user-active-applications: 1 #queue-pending-applications: 0 #queue-active-applications: 1
2016-02-19 14:17:41,501 INFO org.apache.hadoop.yarn.server.resourcemanager.scheduler.capacity.LeafQueue: not starting application as amIfStarted exceeds amLimit
2016-02-19 14:17:41,501 INFO org.apache.hadoop.yarn.server.resourcemanager.scheduler.capacity.LeafQueue: Application added - appId: application_1455908661391_0002 user: org.apache.hadoop.yarn.server.resourcemanager.scheduler.capacity.LeafQueue$User@5552749, leaf-queue: default #user-pending-applications: 1 #user-active-applications: 1 #queue-pending-applications: 1 #queue-active-applications: 1
2016-02-19 14:17:41,502 INFO org.apache.hadoop.yarn.server.resourcemanager.scheduler.capacity.CapacityScheduler: Added Application Attempt appattempt_1455908661391_0002_000002 to scheduler from user jon in queue default
2016-02-19 14:17:41,535 INFO org.apache.hadoop.yarn.server.resourcemanager.rmapp.attempt.RMAppAttemptImpl: appattempt_1455908661391_0002_000002 State change from SUBMITTED to SCHEDULED
2016-02-19 14:17:41,563 INFO org.apache.hadoop.yarn.server.resourcemanager.rmcontainer.RMContainerImpl: container_1455908661391_0003_01_000001 Container Transitioned from NEW to ALLOCATED
2016-02-19 14:17:41,563 INFO org.apache.hadoop.yarn.server.resourcemanager.RMAuditLogger: USER=jon	OPERATION=AM Allocated Container	TARGET=SchedulerApp	RESULT=SUCCESS	APPID=application_1455908661391_0003	CONTAINERID=container_1455908661391_0003_01_000001
2016-02-19 14:17:41,563 INFO org.apache.hadoop.yarn.server.resourcemanager.scheduler.SchedulerNode: Assigned container container_1455908661391_0003_01_000001 of capacity <memory:2048, vCores:1> on host ubuntu:48650, which has 1 containers, <memory:2048, vCores:1> used and <memory:6144, vCores:7> available after allocation
2016-02-19 14:17:41,563 INFO org.apache.hadoop.yarn.server.resourcemanager.scheduler.capacity.LeafQueue: assignedContainer application attempt=appattempt_1455908661391_0003_000001 container=Container: [ContainerId: container_1455908661391_0003_01_000001, NodeId: ubuntu:48650, NodeHttpAddress: ubuntu:8042, Resource: <memory:2048, vCores:1>, Priority: 0, Token: null, ] queue=default: capacity=1.0, absoluteCapacity=1.0, usedResources=<memory:0, vCores:0>, usedCapacity=0.0, absoluteUsedCapacity=0.0, numApps=2, numContainers=0 clusterResource=<memory:8192, vCores:8>
2016-02-19 14:17:41,563 INFO org.apache.hadoop.yarn.server.resourcemanager.scheduler.capacity.ParentQueue: Re-sorting assigned queue: root.default stats: default: capacity=1.0, absoluteCapacity=1.0, usedResources=<memory:2048, vCores:1>, usedCapacity=0.25, absoluteUsedCapacity=0.25, numApps=2, numContainers=1
2016-02-19 14:17:41,564 INFO org.apache.hadoop.yarn.server.resourcemanager.scheduler.capacity.ParentQueue: assignedContainer queue=root usedCapacity=0.25 absoluteUsedCapacity=0.25 used=<memory:2048, vCores:1> cluster=<memory:8192, vCores:8>
2016-02-19 14:17:41,568 INFO org.apache.hadoop.yarn.server.resourcemanager.security.NMTokenSecretManagerInRM: Sending NMToken for nodeId : ubuntu:48650 for container : container_1455908661391_0003_01_000001
2016-02-19 14:17:41,606 INFO org.apache.hadoop.yarn.server.resourcemanager.rmcontainer.RMContainerImpl: container_1455908661391_0003_01_000001 Container Transitioned from ALLOCATED to ACQUIRED
2016-02-19 14:17:41,607 INFO org.apache.hadoop.yarn.server.resourcemanager.security.NMTokenSecretManagerInRM: Clear node set for appattempt_1455908661391_0003_000001
2016-02-19 14:17:41,609 INFO org.apache.hadoop.yarn.server.resourcemanager.rmapp.attempt.RMAppAttemptImpl: Storing attempt: AppId: application_1455908661391_0003 AttemptId: appattempt_1455908661391_0003_000001 MasterContainer: Container: [ContainerId: container_1455908661391_0003_01_000001, NodeId: ubuntu:48650, NodeHttpAddress: ubuntu:8042, Resource: <memory:2048, vCores:1>, Priority: 0, Token: Token { kind: ContainerToken, service: 127.0.1.1:48650 }, ]
2016-02-19 14:17:41,609 INFO org.apache.hadoop.yarn.server.resourcemanager.rmapp.attempt.RMAppAttemptImpl: appattempt_1455908661391_0003_000001 State change from SCHEDULED to ALLOCATED_SAVING
2016-02-19 14:17:41,609 INFO org.apache.hadoop.yarn.server.resourcemanager.rmapp.attempt.RMAppAttemptImpl: appattempt_1455908661391_0003_000001 State change from ALLOCATED_SAVING to ALLOCATED
2016-02-19 14:17:41,611 INFO org.apache.hadoop.yarn.server.resourcemanager.amlauncher.AMLauncher: Launching masterappattempt_1455908661391_0003_000001
2016-02-19 14:17:41,615 INFO org.apache.hadoop.yarn.server.resourcemanager.amlauncher.AMLauncher: Setting up container Container: [ContainerId: container_1455908661391_0003_01_000001, NodeId: ubuntu:48650, NodeHttpAddress: ubuntu:8042, Resource: <memory:2048, vCores:1>, Priority: 0, Token: Token { kind: ContainerToken, service: 127.0.1.1:48650 }, ] for AM appattempt_1455908661391_0003_000001
2016-02-19 14:17:41,615 INFO org.apache.hadoop.yarn.server.resourcemanager.amlauncher.AMLauncher: Command to launch container container_1455908661391_0003_01_000001 : $JAVA_HOME/bin/java -Dlog4j.configuration=container-log4j.properties -Dyarn.app.container.log.dir=<LOG_DIR> -Dyarn.app.container.log.filesize=0 -Dhadoop.root.logger=INFO,CLA  -Xmx1024m org.apache.hadoop.mapreduce.v2.app.MRAppMaster 1><LOG_DIR>/stdout 2><LOG_DIR>/stderr 
2016-02-19 14:17:41,616 INFO org.apache.hadoop.yarn.server.resourcemanager.security.AMRMTokenSecretManager: Create AMRMToken for ApplicationAttempt: appattempt_1455908661391_0003_000001
2016-02-19 14:17:41,616 INFO org.apache.hadoop.yarn.server.resourcemanager.security.AMRMTokenSecretManager: Creating password for appattempt_1455908661391_0003_000001
2016-02-19 14:17:41,651 INFO org.apache.hadoop.yarn.server.resourcemanager.amlauncher.AMLauncher: Done launching container Container: [ContainerId: container_1455908661391_0003_01_000001, NodeId: ubuntu:48650, NodeHttpAddress: ubuntu:8042, Resource: <memory:2048, vCores:1>, Priority: 0, Token: Token { kind: ContainerToken, service: 127.0.1.1:48650 }, ] for AM appattempt_1455908661391_0003_000001
2016-02-19 14:17:41,651 INFO org.apache.hadoop.yarn.server.resourcemanager.rmapp.attempt.RMAppAttemptImpl: appattempt_1455908661391_0003_000001 State change from ALLOCATED to LAUNCHED
2016-02-19 14:17:42,581 INFO org.apache.hadoop.yarn.server.resourcemanager.rmcontainer.RMContainerImpl: container_1455908661391_0003_01_000001 Container Transitioned from ACQUIRED to RUNNING
2016-02-19 14:17:42,582 INFO org.apache.hadoop.yarn.server.resourcemanager.scheduler.capacity.CapacityScheduler: Null container completed...
2016-02-19 14:17:46,842 INFO SecurityLogger.org.apache.hadoop.ipc.Server: Auth successful for appattempt_1455908661391_0003_000001 (auth:SIMPLE)
2016-02-19 14:17:46,846 INFO org.apache.hadoop.yarn.server.resourcemanager.ApplicationMasterService: AM registration appattempt_1455908661391_0003_000001
2016-02-19 14:17:46,846 INFO org.apache.hadoop.yarn.server.resourcemanager.RMAuditLogger: USER=jon	IP=127.0.0.1	OPERATION=Register App Master	TARGET=ApplicationMasterService	RESULT=SUCCESS	APPID=application_1455908661391_0003	APPATTEMPTID=appattempt_1455908661391_0003_000001
2016-02-19 14:17:46,847 INFO org.apache.hadoop.yarn.server.resourcemanager.rmapp.attempt.RMAppAttemptImpl: appattempt_1455908661391_0003_000001 State change from LAUNCHED to RUNNING
2016-02-19 14:17:46,848 INFO org.apache.hadoop.yarn.server.resourcemanager.rmapp.RMAppImpl: application_1455908661391_0003 State change from ACCEPTED to RUNNING
2016-02-19 14:17:48,601 INFO org.apache.hadoop.yarn.server.resourcemanager.rmcontainer.RMContainerImpl: container_1455908661391_0003_01_000002 Container Transitioned from NEW to ALLOCATED
2016-02-19 14:17:48,602 INFO org.apache.hadoop.yarn.server.resourcemanager.RMAuditLogger: USER=jon	OPERATION=AM Allocated Container	TARGET=SchedulerApp	RESULT=SUCCESS	APPID=application_1455908661391_0003	CONTAINERID=container_1455908661391_0003_01_000002
2016-02-19 14:17:48,602 INFO org.apache.hadoop.yarn.server.resourcemanager.scheduler.SchedulerNode: Assigned container container_1455908661391_0003_01_000002 of capacity <memory:1024, vCores:1> on host ubuntu:48650, which has 2 containers, <memory:3072, vCores:2> used and <memory:5120, vCores:6> available after allocation
2016-02-19 14:17:48,603 INFO org.apache.hadoop.yarn.server.resourcemanager.scheduler.capacity.LeafQueue: assignedContainer application attempt=appattempt_1455908661391_0003_000001 container=Container: [ContainerId: container_1455908661391_0003_01_000002, NodeId: ubuntu:48650, NodeHttpAddress: ubuntu:8042, Resource: <memory:1024, vCores:1>, Priority: 20, Token: null, ] queue=default: capacity=1.0, absoluteCapacity=1.0, usedResources=<memory:2048, vCores:1>, usedCapacity=0.25, absoluteUsedCapacity=0.25, numApps=2, numContainers=1 clusterResource=<memory:8192, vCores:8>
2016-02-19 14:17:48,603 INFO org.apache.hadoop.yarn.server.resourcemanager.scheduler.capacity.ParentQueue: Re-sorting assigned queue: root.default stats: default: capacity=1.0, absoluteCapacity=1.0, usedResources=<memory:3072, vCores:2>, usedCapacity=0.375, absoluteUsedCapacity=0.375, numApps=2, numContainers=2
2016-02-19 14:17:48,604 INFO org.apache.hadoop.yarn.server.resourcemanager.scheduler.capacity.ParentQueue: assignedContainer queue=root usedCapacity=0.375 absoluteUsedCapacity=0.375 used=<memory:3072, vCores:2> cluster=<memory:8192, vCores:8>
2016-02-19 14:17:49,006 INFO org.apache.hadoop.yarn.server.resourcemanager.security.NMTokenSecretManagerInRM: Sending NMToken for nodeId : ubuntu:48650 for container : container_1455908661391_0003_01_000002
2016-02-19 14:17:49,008 INFO org.apache.hadoop.yarn.server.resourcemanager.rmcontainer.RMContainerImpl: container_1455908661391_0003_01_000002 Container Transitioned from ALLOCATED to ACQUIRED
2016-02-19 14:17:49,603 INFO org.apache.hadoop.yarn.server.resourcemanager.rmcontainer.RMContainerImpl: container_1455908661391_0003_01_000002 Container Transitioned from ACQUIRED to RUNNING
2016-02-19 14:17:50,033 INFO org.apache.hadoop.yarn.server.resourcemanager.scheduler.AppSchedulingInfo: checking for deactivate... 
2016-02-19 14:17:53,843 INFO org.apache.hadoop.yarn.server.resourcemanager.rmcontainer.RMContainerImpl: container_1455908661391_0003_01_000002 Container Transitioned from RUNNING to COMPLETED
2016-02-19 14:17:53,843 INFO org.apache.hadoop.yarn.server.resourcemanager.scheduler.common.fica.FiCaSchedulerApp: Completed container: container_1455908661391_0003_01_000002 in state: COMPLETED event:FINISHED
2016-02-19 14:17:53,843 INFO org.apache.hadoop.yarn.server.resourcemanager.RMAuditLogger: USER=jon	OPERATION=AM Released Container	TARGET=SchedulerApp	RESULT=SUCCESS	APPID=application_1455908661391_0003	CONTAINERID=container_1455908661391_0003_01_000002
2016-02-19 14:17:53,843 INFO org.apache.hadoop.yarn.server.resourcemanager.scheduler.SchedulerNode: Released container container_1455908661391_0003_01_000002 of capacity <memory:1024, vCores:1> on host ubuntu:48650, which currently has 1 containers, <memory:2048, vCores:1> used and <memory:6144, vCores:7> available, release resources=true
2016-02-19 14:17:53,843 INFO org.apache.hadoop.yarn.server.resourcemanager.scheduler.capacity.LeafQueue: default used=<memory:2048, vCores:1> numContainers=1 user=jon user-resources=<memory:2048, vCores:1>
2016-02-19 14:17:53,844 INFO org.apache.hadoop.yarn.server.resourcemanager.scheduler.capacity.LeafQueue: completedContainer container=Container: [ContainerId: container_1455908661391_0003_01_000002, NodeId: ubuntu:48650, NodeHttpAddress: ubuntu:8042, Resource: <memory:1024, vCores:1>, Priority: 20, Token: Token { kind: ContainerToken, service: 127.0.1.1:48650 }, ] queue=default: capacity=1.0, absoluteCapacity=1.0, usedResources=<memory:2048, vCores:1>, usedCapacity=0.25, absoluteUsedCapacity=0.25, numApps=2, numContainers=1 cluster=<memory:8192, vCores:8>
2016-02-19 14:17:53,844 INFO org.apache.hadoop.yarn.server.resourcemanager.scheduler.capacity.ParentQueue: completedContainer queue=root usedCapacity=0.25 absoluteUsedCapacity=0.25 used=<memory:2048, vCores:1> cluster=<memory:8192, vCores:8>
2016-02-19 14:17:53,845 INFO org.apache.hadoop.yarn.server.resourcemanager.scheduler.capacity.ParentQueue: Re-sorting completed queue: root.default stats: default: capacity=1.0, absoluteCapacity=1.0, usedResources=<memory:2048, vCores:1>, usedCapacity=0.25, absoluteUsedCapacity=0.25, numApps=2, numContainers=1
2016-02-19 14:17:53,845 INFO org.apache.hadoop.yarn.server.resourcemanager.scheduler.capacity.CapacityScheduler: Application attempt appattempt_1455908661391_0003_000001 released container container_1455908661391_0003_01_000002 on node: host: ubuntu:48650 #containers=1 available=6144 used=2048 with event: FINISHED
2016-02-19 14:17:54,844 INFO org.apache.hadoop.yarn.server.resourcemanager.rmcontainer.RMContainerImpl: container_1455908661391_0003_01_000003 Container Transitioned from NEW to ALLOCATED
2016-02-19 14:17:54,845 INFO org.apache.hadoop.yarn.server.resourcemanager.RMAuditLogger: USER=jon	OPERATION=AM Allocated Container	TARGET=SchedulerApp	RESULT=SUCCESS	APPID=application_1455908661391_0003	CONTAINERID=container_1455908661391_0003_01_000003
2016-02-19 14:17:54,845 INFO org.apache.hadoop.yarn.server.resourcemanager.scheduler.SchedulerNode: Assigned container container_1455908661391_0003_01_000003 of capacity <memory:1024, vCores:1> on host ubuntu:48650, which has 2 containers, <memory:3072, vCores:2> used and <memory:5120, vCores:6> available after allocation
2016-02-19 14:17:54,845 INFO org.apache.hadoop.yarn.server.resourcemanager.scheduler.capacity.LeafQueue: assignedContainer application attempt=appattempt_1455908661391_0003_000001 container=Container: [ContainerId: container_1455908661391_0003_01_000003, NodeId: ubuntu:48650, NodeHttpAddress: ubuntu:8042, Resource: <memory:1024, vCores:1>, Priority: 10, Token: null, ] queue=default: capacity=1.0, absoluteCapacity=1.0, usedResources=<memory:2048, vCores:1>, usedCapacity=0.25, absoluteUsedCapacity=0.25, numApps=2, numContainers=1 clusterResource=<memory:8192, vCores:8>
2016-02-19 14:17:54,846 INFO org.apache.hadoop.yarn.server.resourcemanager.scheduler.capacity.ParentQueue: Re-sorting assigned queue: root.default stats: default: capacity=1.0, absoluteCapacity=1.0, usedResources=<memory:3072, vCores:2>, usedCapacity=0.375, absoluteUsedCapacity=0.375, numApps=2, numContainers=2
2016-02-19 14:17:54,848 INFO org.apache.hadoop.yarn.server.resourcemanager.scheduler.capacity.ParentQueue: assignedContainer queue=root usedCapacity=0.375 absoluteUsedCapacity=0.375 used=<memory:3072, vCores:2> cluster=<memory:8192, vCores:8>
2016-02-19 14:17:55,130 INFO org.apache.hadoop.yarn.server.resourcemanager.rmcontainer.RMContainerImpl: container_1455908661391_0003_01_000003 Container Transitioned from ALLOCATED to ACQUIRED
2016-02-19 14:17:55,849 INFO org.apache.hadoop.yarn.server.resourcemanager.rmcontainer.RMContainerImpl: container_1455908661391_0003_01_000003 Container Transitioned from ACQUIRED to RUNNING
2016-02-19 14:17:56,136 INFO org.apache.hadoop.yarn.server.resourcemanager.scheduler.AppSchedulingInfo: checking for deactivate... 
2016-02-19 14:18:00,579 INFO org.apache.hadoop.yarn.server.resourcemanager.rmapp.attempt.RMAppAttemptImpl: Updating application attempt appattempt_1455908661391_0003_000001 with final state: FINISHING, and exit status: -1000
2016-02-19 14:18:00,580 INFO org.apache.hadoop.yarn.server.resourcemanager.rmapp.attempt.RMAppAttemptImpl: appattempt_1455908661391_0003_000001 State change from RUNNING to FINAL_SAVING
2016-02-19 14:18:00,580 INFO org.apache.hadoop.yarn.server.resourcemanager.rmapp.RMAppImpl: Updating application application_1455908661391_0003 with final state: FINISHING
2016-02-19 14:18:00,580 INFO org.apache.hadoop.yarn.server.resourcemanager.rmapp.RMAppImpl: application_1455908661391_0003 State change from RUNNING to FINAL_SAVING
2016-02-19 14:18:00,580 INFO org.apache.hadoop.yarn.server.resourcemanager.rmapp.attempt.RMAppAttemptImpl: appattempt_1455908661391_0003_000001 State change from FINAL_SAVING to FINISHING
2016-02-19 14:18:00,580 INFO org.apache.hadoop.yarn.server.resourcemanager.recovery.RMStateStore: Updating info for app: application_1455908661391_0003
2016-02-19 14:18:00,580 INFO org.apache.hadoop.yarn.server.resourcemanager.rmapp.RMAppImpl: application_1455908661391_0003 State change from FINAL_SAVING to FINISHING
2016-02-19 14:18:01,365 INFO org.apache.hadoop.yarn.server.resourcemanager.rmcontainer.RMContainerImpl: container_1455908661391_0003_01_000003 Container Transitioned from RUNNING to COMPLETED
2016-02-19 14:18:01,365 INFO org.apache.hadoop.yarn.server.resourcemanager.scheduler.common.fica.FiCaSchedulerApp: Completed container: container_1455908661391_0003_01_000003 in state: COMPLETED event:FINISHED
2016-02-19 14:18:01,365 INFO org.apache.hadoop.yarn.server.resourcemanager.RMAuditLogger: USER=jon	OPERATION=AM Released Container	TARGET=SchedulerApp	RESULT=SUCCESS	APPID=application_1455908661391_0003	CONTAINERID=container_1455908661391_0003_01_000003
2016-02-19 14:18:01,365 INFO org.apache.hadoop.yarn.server.resourcemanager.scheduler.SchedulerNode: Released container container_1455908661391_0003_01_000003 of capacity <memory:1024, vCores:1> on host ubuntu:48650, which currently has 1 containers, <memory:2048, vCores:1> used and <memory:6144, vCores:7> available, release resources=true
2016-02-19 14:18:01,365 INFO org.apache.hadoop.yarn.server.resourcemanager.scheduler.capacity.LeafQueue: default used=<memory:2048, vCores:1> numContainers=1 user=jon user-resources=<memory:2048, vCores:1>
2016-02-19 14:18:01,366 INFO org.apache.hadoop.yarn.server.resourcemanager.scheduler.capacity.LeafQueue: completedContainer container=Container: [ContainerId: container_1455908661391_0003_01_000003, NodeId: ubuntu:48650, NodeHttpAddress: ubuntu:8042, Resource: <memory:1024, vCores:1>, Priority: 10, Token: Token { kind: ContainerToken, service: 127.0.1.1:48650 }, ] queue=default: capacity=1.0, absoluteCapacity=1.0, usedResources=<memory:2048, vCores:1>, usedCapacity=0.25, absoluteUsedCapacity=0.25, numApps=2, numContainers=1 cluster=<memory:8192, vCores:8>
2016-02-19 14:18:01,366 INFO org.apache.hadoop.yarn.server.resourcemanager.scheduler.capacity.ParentQueue: completedContainer queue=root usedCapacity=0.25 absoluteUsedCapacity=0.25 used=<memory:2048, vCores:1> cluster=<memory:8192, vCores:8>
2016-02-19 14:18:01,366 INFO org.apache.hadoop.yarn.server.resourcemanager.scheduler.capacity.ParentQueue: Re-sorting completed queue: root.default stats: default: capacity=1.0, absoluteCapacity=1.0, usedResources=<memory:2048, vCores:1>, usedCapacity=0.25, absoluteUsedCapacity=0.25, numApps=2, numContainers=1
2016-02-19 14:18:01,366 INFO org.apache.hadoop.yarn.server.resourcemanager.scheduler.capacity.CapacityScheduler: Application attempt appattempt_1455908661391_0003_000001 released container container_1455908661391_0003_01_000003 on node: host: ubuntu:48650 #containers=1 available=6144 used=2048 with event: FINISHED
2016-02-19 14:18:01,586 INFO org.apache.hadoop.yarn.server.resourcemanager.ApplicationMasterService: application_1455908661391_0003 unregistered successfully. 
2016-02-19 14:18:07,385 INFO org.apache.hadoop.yarn.server.resourcemanager.rmcontainer.RMContainerImpl: container_1455908661391_0003_01_000001 Container Transitioned from RUNNING to COMPLETED
2016-02-19 14:18:07,385 INFO org.apache.hadoop.yarn.server.resourcemanager.scheduler.common.fica.FiCaSchedulerApp: Completed container: container_1455908661391_0003_01_000001 in state: COMPLETED event:FINISHED
2016-02-19 14:18:07,385 INFO org.apache.hadoop.yarn.server.resourcemanager.RMAuditLogger: USER=jon	OPERATION=AM Released Container	TARGET=SchedulerApp	RESULT=SUCCESS	APPID=application_1455908661391_0003	CONTAINERID=container_1455908661391_0003_01_000001
2016-02-19 14:18:07,385 INFO org.apache.hadoop.yarn.server.resourcemanager.scheduler.SchedulerNode: Released container container_1455908661391_0003_01_000001 of capacity <memory:2048, vCores:1> on host ubuntu:48650, which currently has 0 containers, <memory:0, vCores:0> used and <memory:8192, vCores:8> available, release resources=true
2016-02-19 14:18:07,385 INFO org.apache.hadoop.yarn.server.resourcemanager.scheduler.capacity.LeafQueue: default used=<memory:0, vCores:0> numContainers=0 user=jon user-resources=<memory:0, vCores:0>
2016-02-19 14:18:07,386 INFO org.apache.hadoop.yarn.server.resourcemanager.scheduler.capacity.LeafQueue: completedContainer container=Container: [ContainerId: container_1455908661391_0003_01_000001, NodeId: ubuntu:48650, NodeHttpAddress: ubuntu:8042, Resource: <memory:2048, vCores:1>, Priority: 0, Token: Token { kind: ContainerToken, service: 127.0.1.1:48650 }, ] queue=default: capacity=1.0, absoluteCapacity=1.0, usedResources=<memory:0, vCores:0>, usedCapacity=0.0, absoluteUsedCapacity=0.0, numApps=2, numContainers=0 cluster=<memory:8192, vCores:8>
2016-02-19 14:18:07,386 INFO org.apache.hadoop.yarn.server.resourcemanager.scheduler.capacity.ParentQueue: completedContainer queue=root usedCapacity=0.0 absoluteUsedCapacity=0.0 used=<memory:0, vCores:0> cluster=<memory:8192, vCores:8>
2016-02-19 14:18:07,386 INFO org.apache.hadoop.yarn.server.resourcemanager.scheduler.capacity.ParentQueue: Re-sorting completed queue: root.default stats: default: capacity=1.0, absoluteCapacity=1.0, usedResources=<memory:0, vCores:0>, usedCapacity=0.0, absoluteUsedCapacity=0.0, numApps=2, numContainers=0
2016-02-19 14:18:07,386 INFO org.apache.hadoop.yarn.server.resourcemanager.scheduler.capacity.CapacityScheduler: Application attempt appattempt_1455908661391_0003_000001 released container container_1455908661391_0003_01_000001 on node: host: ubuntu:48650 #containers=0 available=8192 used=0 with event: FINISHED
2016-02-19 14:18:07,386 INFO org.apache.hadoop.yarn.server.resourcemanager.ApplicationMasterService: Unregistering app attempt : appattempt_1455908661391_0003_000001
2016-02-19 14:18:07,387 INFO org.apache.hadoop.yarn.server.resourcemanager.security.AMRMTokenSecretManager: Application finished, removing password for appattempt_1455908661391_0003_000001
2016-02-19 14:18:07,387 INFO org.apache.hadoop.yarn.server.resourcemanager.rmapp.attempt.RMAppAttemptImpl: appattempt_1455908661391_0003_000001 State change from FINISHING to FINISHED
2016-02-19 14:18:07,388 INFO org.apache.hadoop.yarn.server.resourcemanager.rmapp.RMAppImpl: application_1455908661391_0003 State change from FINISHING to FINISHED
2016-02-19 14:18:07,388 INFO org.apache.hadoop.yarn.server.resourcemanager.scheduler.capacity.CapacityScheduler: Application Attempt appattempt_1455908661391_0003_000001 is done. finalState=FINISHED
2016-02-19 14:18:07,389 INFO org.apache.hadoop.yarn.server.resourcemanager.scheduler.AppSchedulingInfo: Application application_1455908661391_0003 requests cleared
2016-02-19 14:18:07,391 WARN org.apache.hadoop.yarn.server.resourcemanager.scheduler.capacity.LeafQueue: maximum-am-resource-percent is insufficient to start a single application in queue, it is likely set too low. skipping enforcement to allow at least one application to start
2016-02-19 14:18:07,391 WARN org.apache.hadoop.yarn.server.resourcemanager.scheduler.capacity.LeafQueue: maximum-am-resource-percent is insufficient to start a single application in queue for user, it is likely set too low. skipping enforcement to allow at least one application to start
2016-02-19 14:18:07,392 INFO org.apache.hadoop.yarn.server.resourcemanager.RMAuditLogger: USER=jon	OPERATION=Application Finished - Succeeded	TARGET=RMAppManager	RESULT=SUCCESS	APPID=application_1455908661391_0003
2016-02-19 14:18:07,392 INFO org.apache.hadoop.yarn.server.resourcemanager.RMAppManager$ApplicationSummary: appId=application_1455908661391_0003,name=MissedConnectionAnalysis,user=jon,queue=default,state=FINISHED,trackingUrl=http://ubuntu:8088/proxy/application_1455908661391_0003/,appMasterHost=ubuntu,startTime=1455908758293,finishTime=1455909480580,finalStatus=SUCCEEDED
2016-02-19 14:18:07,392 INFO org.apache.hadoop.yarn.server.resourcemanager.scheduler.capacity.LeafQueue: Application application_1455908661391_0002 from user: jon activated in queue: default
2016-02-19 14:18:07,393 INFO org.apache.hadoop.yarn.server.resourcemanager.scheduler.capacity.LeafQueue: Application removed - appId: application_1455908661391_0003 user: jon queue: default #user-pending-applications: 0 #user-active-applications: 1 #queue-pending-applications: 0 #queue-active-applications: 1
2016-02-19 14:18:07,393 INFO org.apache.hadoop.yarn.server.resourcemanager.scheduler.capacity.ParentQueue: Application removed - appId: application_1455908661391_0003 user: jon leaf-queue of parent: root #applications: 1
2016-02-19 14:18:07,395 INFO org.apache.hadoop.yarn.server.resourcemanager.amlauncher.AMLauncher: Cleaning master appattempt_1455908661391_0003_000001
2016-02-19 14:18:07,440 INFO org.apache.hadoop.yarn.server.resourcemanager.rmcontainer.RMContainerImpl: container_1455908661391_0002_02_000001 Container Transitioned from NEW to ALLOCATED
2016-02-19 14:18:07,440 INFO org.apache.hadoop.yarn.server.resourcemanager.RMAuditLogger: USER=jon	OPERATION=AM Allocated Container	TARGET=SchedulerApp	RESULT=SUCCESS	APPID=application_1455908661391_0002	CONTAINERID=container_1455908661391_0002_02_000001
2016-02-19 14:18:07,441 INFO org.apache.hadoop.yarn.server.resourcemanager.scheduler.SchedulerNode: Assigned container container_1455908661391_0002_02_000001 of capacity <memory:2048, vCores:1> on host ubuntu:48650, which has 1 containers, <memory:2048, vCores:1> used and <memory:6144, vCores:7> available after allocation
2016-02-19 14:18:07,442 INFO org.apache.hadoop.yarn.server.resourcemanager.scheduler.capacity.LeafQueue: assignedContainer application attempt=appattempt_1455908661391_0002_000002 container=Container: [ContainerId: container_1455908661391_0002_02_000001, NodeId: ubuntu:48650, NodeHttpAddress: ubuntu:8042, Resource: <memory:2048, vCores:1>, Priority: 0, Token: null, ] queue=default: capacity=1.0, absoluteCapacity=1.0, usedResources=<memory:0, vCores:0>, usedCapacity=0.0, absoluteUsedCapacity=0.0, numApps=1, numContainers=0 clusterResource=<memory:8192, vCores:8>
2016-02-19 14:18:07,442 INFO org.apache.hadoop.yarn.server.resourcemanager.scheduler.capacity.ParentQueue: Re-sorting assigned queue: root.default stats: default: capacity=1.0, absoluteCapacity=1.0, usedResources=<memory:2048, vCores:1>, usedCapacity=0.25, absoluteUsedCapacity=0.25, numApps=1, numContainers=1
2016-02-19 14:18:07,442 INFO org.apache.hadoop.yarn.server.resourcemanager.scheduler.capacity.ParentQueue: assignedContainer queue=root usedCapacity=0.25 absoluteUsedCapacity=0.25 used=<memory:2048, vCores:1> cluster=<memory:8192, vCores:8>
2016-02-19 14:18:07,490 INFO org.apache.hadoop.yarn.server.resourcemanager.security.NMTokenSecretManagerInRM: Sending NMToken for nodeId : ubuntu:48650 for container : container_1455908661391_0002_02_000001
2016-02-19 14:18:07,492 INFO org.apache.hadoop.yarn.server.resourcemanager.rmcontainer.RMContainerImpl: container_1455908661391_0002_02_000001 Container Transitioned from ALLOCATED to ACQUIRED
2016-02-19 14:18:07,492 INFO org.apache.hadoop.yarn.server.resourcemanager.security.NMTokenSecretManagerInRM: Clear node set for appattempt_1455908661391_0002_000002
2016-02-19 14:18:07,492 INFO org.apache.hadoop.yarn.server.resourcemanager.rmapp.attempt.RMAppAttemptImpl: Storing attempt: AppId: application_1455908661391_0002 AttemptId: appattempt_1455908661391_0002_000002 MasterContainer: Container: [ContainerId: container_1455908661391_0002_02_000001, NodeId: ubuntu:48650, NodeHttpAddress: ubuntu:8042, Resource: <memory:2048, vCores:1>, Priority: 0, Token: Token { kind: ContainerToken, service: 127.0.1.1:48650 }, ]
2016-02-19 14:18:07,492 INFO org.apache.hadoop.yarn.server.resourcemanager.rmapp.attempt.RMAppAttemptImpl: appattempt_1455908661391_0002_000002 State change from SCHEDULED to ALLOCATED_SAVING
2016-02-19 14:18:07,493 INFO org.apache.hadoop.yarn.server.resourcemanager.rmapp.attempt.RMAppAttemptImpl: appattempt_1455908661391_0002_000002 State change from ALLOCATED_SAVING to ALLOCATED
2016-02-19 14:18:07,493 INFO org.apache.hadoop.yarn.server.resourcemanager.amlauncher.AMLauncher: Launching masterappattempt_1455908661391_0002_000002
2016-02-19 14:18:07,501 INFO org.apache.hadoop.yarn.server.resourcemanager.amlauncher.AMLauncher: Setting up container Container: [ContainerId: container_1455908661391_0002_02_000001, NodeId: ubuntu:48650, NodeHttpAddress: ubuntu:8042, Resource: <memory:2048, vCores:1>, Priority: 0, Token: Token { kind: ContainerToken, service: 127.0.1.1:48650 }, ] for AM appattempt_1455908661391_0002_000002
2016-02-19 14:18:07,501 INFO org.apache.hadoop.yarn.server.resourcemanager.amlauncher.AMLauncher: Command to launch container container_1455908661391_0002_02_000001 : $JAVA_HOME/bin/java -Dlog4j.configuration=container-log4j.properties -Dyarn.app.container.log.dir=<LOG_DIR> -Dyarn.app.container.log.filesize=0 -Dhadoop.root.logger=INFO,CLA  -Xmx1024m org.apache.hadoop.mapreduce.v2.app.MRAppMaster 1><LOG_DIR>/stdout 2><LOG_DIR>/stderr 
2016-02-19 14:18:07,503 INFO org.apache.hadoop.yarn.server.resourcemanager.security.AMRMTokenSecretManager: Create AMRMToken for ApplicationAttempt: appattempt_1455908661391_0002_000002
2016-02-19 14:18:07,503 INFO org.apache.hadoop.yarn.server.resourcemanager.security.AMRMTokenSecretManager: Creating password for appattempt_1455908661391_0002_000002
2016-02-19 14:18:07,549 INFO org.apache.hadoop.yarn.server.resourcemanager.amlauncher.AMLauncher: Done launching container Container: [ContainerId: container_1455908661391_0002_02_000001, NodeId: ubuntu:48650, NodeHttpAddress: ubuntu:8042, Resource: <memory:2048, vCores:1>, Priority: 0, Token: Token { kind: ContainerToken, service: 127.0.1.1:48650 }, ] for AM appattempt_1455908661391_0002_000002
2016-02-19 14:18:07,549 INFO org.apache.hadoop.yarn.server.resourcemanager.rmapp.attempt.RMAppAttemptImpl: appattempt_1455908661391_0002_000002 State change from ALLOCATED to LAUNCHED
2016-02-19 14:18:08,476 INFO org.apache.hadoop.yarn.server.resourcemanager.rmcontainer.RMContainerImpl: container_1455908661391_0002_02_000001 Container Transitioned from ACQUIRED to RUNNING
2016-02-19 14:18:08,477 INFO org.apache.hadoop.yarn.server.resourcemanager.scheduler.capacity.CapacityScheduler: Null container completed...
2016-02-19 14:31:01,472 INFO org.apache.hadoop.yarn.util.AbstractLivelinessMonitor: Expired:appattempt_1455908661391_0002_000002 Timed out after 600 secs
2016-02-19 14:31:01,473 INFO org.apache.hadoop.yarn.server.resourcemanager.rmapp.attempt.RMAppAttemptImpl: Updating application attempt appattempt_1455908661391_0002_000002 with final state: FAILED, and exit status: -1000
2016-02-19 14:31:01,499 INFO org.apache.hadoop.yarn.server.resourcemanager.rmapp.attempt.RMAppAttemptImpl: appattempt_1455908661391_0002_000002 State change from LAUNCHED to FINAL_SAVING
2016-02-19 14:31:01,500 INFO org.apache.hadoop.yarn.server.resourcemanager.ApplicationMasterService: Unregistering app attempt : appattempt_1455908661391_0002_000002
2016-02-19 14:31:01,500 INFO org.apache.hadoop.yarn.server.resourcemanager.security.AMRMTokenSecretManager: Application finished, removing password for appattempt_1455908661391_0002_000002
2016-02-19 14:31:01,500 INFO org.apache.hadoop.yarn.server.resourcemanager.rmapp.attempt.RMAppAttemptImpl: appattempt_1455908661391_0002_000002 State change from FINAL_SAVING to FAILED
2016-02-19 14:31:01,500 INFO org.apache.hadoop.yarn.server.resourcemanager.rmapp.RMAppImpl: The number of failed attempts is 2. The max attempts is 2
2016-02-19 14:31:01,517 INFO org.apache.hadoop.yarn.server.resourcemanager.rmapp.RMAppImpl: Updating application application_1455908661391_0002 with final state: FAILED
2016-02-19 14:31:01,517 INFO org.apache.hadoop.yarn.server.resourcemanager.rmapp.RMAppImpl: application_1455908661391_0002 State change from ACCEPTED to FINAL_SAVING
2016-02-19 14:31:01,517 INFO org.apache.hadoop.yarn.server.resourcemanager.recovery.RMStateStore: Updating info for app: application_1455908661391_0002
2016-02-19 14:31:01,517 INFO org.apache.hadoop.yarn.server.resourcemanager.scheduler.capacity.CapacityScheduler: Application Attempt appattempt_1455908661391_0002_000002 is done. finalState=FAILED
2016-02-19 14:31:01,517 INFO org.apache.hadoop.yarn.server.resourcemanager.rmcontainer.RMContainerImpl: container_1455908661391_0002_02_000001 Container Transitioned from RUNNING to KILLED
2016-02-19 14:31:01,518 INFO org.apache.hadoop.yarn.server.resourcemanager.scheduler.common.fica.FiCaSchedulerApp: Completed container: container_1455908661391_0002_02_000001 in state: KILLED event:KILL
2016-02-19 14:31:01,518 INFO org.apache.hadoop.yarn.server.resourcemanager.RMAuditLogger: USER=jon	OPERATION=AM Released Container	TARGET=SchedulerApp	RESULT=SUCCESS	APPID=application_1455908661391_0002	CONTAINERID=container_1455908661391_0002_02_000001
2016-02-19 14:31:01,518 INFO org.apache.hadoop.yarn.server.resourcemanager.scheduler.SchedulerNode: Released container container_1455908661391_0002_02_000001 of capacity <memory:2048, vCores:1> on host ubuntu:48650, which currently has 0 containers, <memory:0, vCores:0> used and <memory:8192, vCores:8> available, release resources=true
2016-02-19 14:31:01,518 INFO org.apache.hadoop.yarn.server.resourcemanager.scheduler.capacity.LeafQueue: default used=<memory:0, vCores:0> numContainers=0 user=jon user-resources=<memory:0, vCores:0>
2016-02-19 14:31:01,518 INFO org.apache.hadoop.yarn.server.resourcemanager.scheduler.capacity.LeafQueue: completedContainer container=Container: [ContainerId: container_1455908661391_0002_02_000001, NodeId: ubuntu:48650, NodeHttpAddress: ubuntu:8042, Resource: <memory:2048, vCores:1>, Priority: 0, Token: Token { kind: ContainerToken, service: 127.0.1.1:48650 }, ] queue=default: capacity=1.0, absoluteCapacity=1.0, usedResources=<memory:0, vCores:0>, usedCapacity=0.0, absoluteUsedCapacity=0.0, numApps=1, numContainers=0 cluster=<memory:8192, vCores:8>
2016-02-19 14:31:01,518 INFO org.apache.hadoop.yarn.server.resourcemanager.scheduler.capacity.ParentQueue: completedContainer queue=root usedCapacity=0.0 absoluteUsedCapacity=0.0 used=<memory:0, vCores:0> cluster=<memory:8192, vCores:8>
2016-02-19 14:31:01,518 INFO org.apache.hadoop.yarn.server.resourcemanager.scheduler.capacity.ParentQueue: Re-sorting completed queue: root.default stats: default: capacity=1.0, absoluteCapacity=1.0, usedResources=<memory:0, vCores:0>, usedCapacity=0.0, absoluteUsedCapacity=0.0, numApps=1, numContainers=0
2016-02-19 14:31:01,518 INFO org.apache.hadoop.yarn.server.resourcemanager.scheduler.capacity.CapacityScheduler: Application attempt appattempt_1455908661391_0002_000002 released container container_1455908661391_0002_02_000001 on node: host: ubuntu:48650 #containers=0 available=8192 used=0 with event: KILL
2016-02-19 14:31:01,518 INFO org.apache.hadoop.yarn.server.resourcemanager.scheduler.AppSchedulingInfo: Application application_1455908661391_0002 requests cleared
2016-02-19 14:31:01,518 INFO org.apache.hadoop.yarn.server.resourcemanager.scheduler.capacity.LeafQueue: Application removed - appId: application_1455908661391_0002 user: jon queue: default #user-pending-applications: 0 #user-active-applications: 0 #queue-pending-applications: 0 #queue-active-applications: 0
2016-02-19 14:31:01,518 INFO org.apache.hadoop.yarn.server.resourcemanager.rmapp.RMAppImpl: Application application_1455908661391_0002 failed 2 times due to ApplicationMaster for attempt appattempt_1455908661391_0002_000002 timed out. Failing the application.
2016-02-19 14:31:01,522 INFO org.apache.hadoop.yarn.server.resourcemanager.amlauncher.AMLauncher: Cleaning master appattempt_1455908661391_0002_000002
2016-02-19 14:31:01,522 INFO org.apache.hadoop.yarn.server.resourcemanager.rmapp.RMAppImpl: application_1455908661391_0002 State change from FINAL_SAVING to FAILED
2016-02-19 14:31:01,522 INFO org.apache.hadoop.yarn.server.resourcemanager.scheduler.capacity.ParentQueue: Application removed - appId: application_1455908661391_0002 user: jon leaf-queue of parent: root #applications: 0
2016-02-19 14:31:01,523 WARN org.apache.hadoop.yarn.server.resourcemanager.RMAuditLogger: USER=jon	OPERATION=Application Finished - Failed	TARGET=RMAppManager	RESULT=FAILURE	DESCRIPTION=App failed with state: FAILED	PERMISSIONS=Application application_1455908661391_0002 failed 2 times due to ApplicationMaster for attempt appattempt_1455908661391_0002_000002 timed out. Failing the application.	APPID=application_1455908661391_0002
2016-02-19 14:31:01,523 INFO org.apache.hadoop.yarn.server.resourcemanager.RMAppManager$ApplicationSummary: appId=application_1455908661391_0002,name=MissedConnectionAnalysis,user=jon,queue=default,state=FAILED,trackingUrl=http://ubuntu:8088/cluster/app/application_1455908661391_0002,appMasterHost=N/A,startTime=1455908757941,finishTime=1455910261517,finalStatus=FAILED
2016-02-19 14:31:02,590 INFO org.apache.hadoop.yarn.server.resourcemanager.scheduler.capacity.CapacityScheduler: Null container completed...
2016-02-19 14:31:02,590 INFO org.apache.hadoop.yarn.server.resourcemanager.scheduler.capacity.CapacityScheduler: Null container completed...
2016-02-19 15:05:09,685 ERROR org.apache.hadoop.yarn.server.resourcemanager.ResourceManager: RECEIVED SIGNAL 15: SIGTERM
2016-02-19 15:05:09,812 ERROR org.apache.hadoop.security.token.delegation.AbstractDelegationTokenSecretManager: ExpiredTokenRemover received java.lang.InterruptedException: sleep interrupted
2016-02-19 15:05:09,822 INFO org.mortbay.log: Stopped HttpServer2$SelectChannelConnectorWithSafeStartup@localhost:8088
2016-02-19 15:05:09,822 ERROR org.apache.hadoop.security.token.delegation.AbstractDelegationTokenSecretManager: ExpiredTokenRemover received java.lang.InterruptedException: sleep interrupted
2016-02-19 15:05:09,824 ERROR org.apache.hadoop.security.token.delegation.AbstractDelegationTokenSecretManager: ExpiredTokenRemover received java.lang.InterruptedException: sleep interrupted
2016-02-19 15:05:09,825 INFO org.apache.hadoop.ipc.Server: Stopping server on 8032
2016-02-19 15:05:09,835 INFO org.apache.hadoop.ipc.Server: Stopping IPC Server listener on 8032
2016-02-19 15:05:09,836 INFO org.apache.hadoop.ipc.Server: Stopping IPC Server Responder
2016-02-19 15:05:09,838 INFO org.apache.hadoop.ipc.Server: Stopping server on 8033
2016-02-19 15:05:09,842 INFO org.apache.hadoop.ipc.Server: Stopping IPC Server listener on 8033
2016-02-19 15:05:09,842 INFO org.apache.hadoop.ipc.Server: Stopping IPC Server Responder
2016-02-19 15:05:09,843 INFO org.apache.hadoop.yarn.server.resourcemanager.ResourceManager: Transitioning to standby state
2016-02-19 15:05:09,843 WARN org.apache.hadoop.yarn.server.resourcemanager.amlauncher.ApplicationMasterLauncher: org.apache.hadoop.yarn.server.resourcemanager.amlauncher.ApplicationMasterLauncher$LauncherThread interrupted. Returning.
2016-02-19 15:05:09,844 INFO org.apache.hadoop.ipc.Server: Stopping server on 8030
2016-02-19 15:05:09,846 INFO org.apache.hadoop.ipc.Server: Stopping IPC Server listener on 8030
2016-02-19 15:05:09,847 INFO org.apache.hadoop.ipc.Server: Stopping server on 8031
2016-02-19 15:05:09,848 INFO org.apache.hadoop.ipc.Server: Stopping IPC Server Responder
2016-02-19 15:05:09,859 INFO org.apache.hadoop.ipc.Server: Stopping IPC Server Responder
2016-02-19 15:05:09,859 INFO org.apache.hadoop.ipc.Server: Stopping IPC Server listener on 8031
2016-02-19 15:05:09,861 INFO org.apache.hadoop.yarn.util.AbstractLivelinessMonitor: NMLivelinessMonitor thread interrupted
2016-02-19 15:05:09,861 ERROR org.apache.hadoop.yarn.server.resourcemanager.ResourceManager: Returning, interrupted : java.lang.InterruptedException
2016-02-19 15:05:09,863 INFO org.apache.hadoop.yarn.util.AbstractLivelinessMonitor: org.apache.hadoop.yarn.server.resourcemanager.rmcontainer.ContainerAllocationExpirer thread interrupted
2016-02-19 15:05:09,863 INFO org.apache.hadoop.yarn.util.AbstractLivelinessMonitor: AMLivelinessMonitor thread interrupted
2016-02-19 15:05:09,863 INFO org.apache.hadoop.yarn.util.AbstractLivelinessMonitor: AMLivelinessMonitor thread interrupted
2016-02-19 15:05:09,863 ERROR org.apache.hadoop.security.token.delegation.AbstractDelegationTokenSecretManager: ExpiredTokenRemover received java.lang.InterruptedException: sleep interrupted
2016-02-19 15:05:09,864 INFO org.apache.hadoop.metrics2.impl.MetricsSystemImpl: Stopping ResourceManager metrics system...
2016-02-19 15:05:09,869 INFO org.apache.hadoop.metrics2.impl.MetricsSystemImpl: ResourceManager metrics system stopped.
2016-02-19 15:05:09,870 INFO org.apache.hadoop.metrics2.impl.MetricsSystemImpl: ResourceManager metrics system shutdown complete.
2016-02-19 15:05:09,870 INFO org.apache.hadoop.yarn.event.AsyncDispatcher: AsyncDispatcher is draining to stop, igonring any new events.
2016-02-19 15:05:09,870 INFO org.apache.hadoop.yarn.server.resourcemanager.ResourceManager: Transitioned to standby state
2016-02-19 15:05:09,872 INFO org.apache.hadoop.yarn.server.resourcemanager.ResourceManager: SHUTDOWN_MSG: 
/************************************************************
SHUTDOWN_MSG: Shutting down ResourceManager at ubuntu/127.0.1.1
************************************************************/
